Workbook

Sheet Work Plan - Review SP (WIP)
B1: Design Due Dates
B2: Workstream | C2: Owner | D2: NH upfront clarifcation needed? | E2: PRD (sent to NH for review) | F2: NH Sign Off | G2: VIGO: UI/UX Design | H2: Internal: UI/UX Design | I2: SA (Technical Solution Design) | J2: All Design Activities Due Date | K2: Epics | L2: Story Point Estimate for Dev | N2: Assumed Estimate | O2: Team Days (current 25SP/d)
B3: Estimate Build – Carbon | C3: Venkatesh & Funsho | E3: 46015 | F3: 46021 | G3: 46038 | H3: N/A | I3: =G3+7 -> 46045 | J3: =I3 -> 46045 | K3: VER10-8954, VER10-9428, VER10-9464, VER10-9527, VER10-9523 | L3: 575 | M3: 414 | O3: =SUM(L3:N3) / Capacity!$B$2 -> 141.28571
B4: Interim Forecasting Tool | C4: Venkatesh | E4: 46031 | F4: 46035 | G4: 46043 | H4: N/A | I4: =G4+7 -> 46050 | J4: =I4 -> 46050 | K4: VER10-8678, VER10-8680, VER10-8682, VER10-8858,, VER10-8679, VER10-8921, VER10-9049,, VER10-9128, | L4: 177 | M4: 200 | O4: =SUM(L4:N4) / Capacity!$B$2 -> 53.857143
B5: Long-Term Appraisal | C5: Funsho | E5: Fri 12 Dec 2025 (Done on time) | F5: 46008 | G5: 46037 | H5: N/A | I5: =G5+7 -> 46044 | J5: =I5 -> 46044 | K5: VER10-8565 | L5: 260 | M5: 200 | O5: =SUM(L5:N5) / Capacity!$B$2 -> 65.714286
B6: Comparator | C6: Funsho | D6: Y | E6: 19/12/2025 (Done on time) | F6: 46015 | G6: 46037 | H6: N/A | I6: =G6+7 -> 46044 | J6: =I6 -> 46044 | K6: VER10-8953 | L6: 120 | M6: 100 | O6: =SUM(L6:N6) / Capacity!$B$2 -> 31.428571
B7: Workflow | C7: Funsho | D7: Y | E7: Wed 17 Dec 2025 (1 day delay) | F7: 46010 | G7: N/A | H7: 46031 | I7: =H7+7 -> 46038 | J7: =I7 -> 46038 | K7: VER10-9028 | L7: 35 | M7: 35 | O7: =SUM(L7:N7) / Capacity!$B$2 -> 10
B8: Tasks | C8: Funsho | E8: Wed 17 Dec 2025 (1 day delay) | F8: 46010 | G8: N/A | H8: 46031 | I8: =H8+7 -> 46038 | J8: =I8 -> 46038 | K8: VER10-9027 | L8: 40 | M8: 0 | O8: =SUM(L8:N8) / Capacity!$B$2 -> 5.7142857
B9: Portfolio/Programme Risk | C9: Funsho | E9: Fri 12 Dec 2025 (Done on time) | F9: 46008 | G9: 46044 | H9: N/A | I9: =G9+7 -> 46051 | J9: =I9 -> 46051 | K9: VER10-9494 | L9: 80 | M9: 60 | O9: =SUM(L9:N9) / Capacity!$B$2 -> 20
B10: Calculators/Cost Models (Chapter 10) | C10: Minas | E10: Thu 18 Dec 2025 (Done on time) | F10: 46015 | G10: N/A | H10: 46031 | I10: =H10+7 -> 46038 | J10: =I10 -> 46038 | K10: No Epic | L10: 20 | M10: 20 | O10: =SUM(L10:N10) / Capacity!$B$2 -> 5.7142857
B11: Scenario Analysis (Chapter 7) | C11: Venkatesh? (TBC) | E11: Fri, 13 Feb 2026 | F11: Fri, 20 Feb 2026 | G11: 46051 | H11: N/A | I11: =G11+7 -> 46058 | J11: =I11 -> 46058 | K11: VER10-8958 | L11: 140 | M11: 100 | O11: =SUM(L11:N11) / Capacity!$B$2 -> 34.285714
B12: Star Rates | C12: Minas? (TBC) | E12: 46045 | F12: 46052 | G12: N/A | H12: 46059 | I12: =H12+7 -> 46066 | J12: =I12 -> 46066 | K12: No Epic | L12: 90 | M12: 60 | O12: =SUM(L12:N12) / Capacity!$B$2 -> 21.428571
B13: TPE | C13: Venkatesh | E13: 46045 | F13: 46050 | G13: 46059 | H13: N/A | I13: =G13+7 -> 46066 | J13: =I13 -> 46066 | K13: VER10-9184 | L13: 350 | M13: 215 | O13: =SUM(L13:N13) / Capacity!$B$2 -> 80.714286
B14: Dashboards (Power BI) | C14: Minas | E14: 46015 | F14: 46022 | G14: 46051 | H14: N/A | I14: =G14+7 -> 46058 | J14: =I14 -> 46058 | K14: No Epic | L14: 40 | M14: 40 | O14: =SUM(L14:N14) / Capacity!$B$2 -> 11.428571
B15: Contractor Fee Library | C15: Minas | E15: 46031 | F15: 46036 | G15: N/A | H15: 46038 | I15: =H15+7 -> 46045 | J15: =I15 -> 46045 | K15: VER10-9271 | L15: 90 | M15: 80 | O15: =SUM(L15:N15) / Capacity!$B$2 -> 24.285714
B16: System Access | C16: Minas | E16: 46038 | F16: N/A | G16: N/A | H16: 46038 | I16: =H16+7 -> 46045 | J16: =I16 -> 46045 | K16: No Epic | L16: 40 | M16: 40 | O16: =SUM(L16:N16) / Capacity!$B$2 -> 11.428571
B17: Audit Log | C17: Minas | E17: 46052 | F17: 46059 | G17: N/A | H17: 46066 | I17: ? | K17: VER10-8955 | L17: 10 | M17: 11 | O17: =SUM(L17:N17) / Capacity!$B$2 -> 3
B18: WBS Tags and Custom Fields | C18: Funsho | E18: Done | F18: Done | G18: Done | H18: Done | I18: Done | J18: Done | K18: VER10-8916, VER10-8268 | L18: Need Estimate | M18: Need Estimate | O18: =SUM(L18:N18) / Capacity!$B$2 -> 0
B19: Reporting Foundation Admin | C19: Funsho | E19: Done | F19: Done | G19: Done | H19: Done | I19: Done | J19: Done | K19: VER10-8476 | L19: 19 | M19: 19 | O19: =SUM(L19:N19) / Capacity!$B$2 -> 5.4285714
B20: Inflation | C20: Funsho | E20: Done | F20: Done | G20: Done | H20: Done | I20: Done | J20: Done | K20: VER10-8903, VER10-8570 | L20: 41 | M20: 41 | O20: =SUM(L20:N20) / Capacity!$B$2 -> 11.714286
B21: AR and O&M fixed reports | E21: Done | F21: Done | G21: Done | H21: Done | I21: Done | J21: Done | K21: VER10-7878, VER10-7879 | L21: 47 | M21: 47 | O21: =SUM(L21:N21) / Capacity!$B$2 -> 13.428571
B22: CCESS | E22: Done | F22: Done | G22: Done | H22: Done | I22: Done | J22: Done | K22: VER10-6966 | L22: 5 | M22: 5 | O22: =SUM(L22:N22) / Capacity!$B$2 -> 1.4285714
L23: =SUM(L3:L22) -> 2179 | M23: =SUM(M3:M22) -> 1687 | O23: =SUM(O3:O22) -> 552.28571

Sheet Capacity
C1: per week | D1: whole team
A2: Required per team per day | B2: 7 | C2: =B2*5 -> 35 | D2: =C2*5 -> 175
A3: Ideal per team per day | B3: 8 | C3: =B3*5 -> 40 | D3: =C3*5 -> 200
A5: per dev per day | C5: =C3/28 -> 1.4285714

Sheet Teams Allocation
C1: # points / week | D1: 46013 | E1: 46020 | F1: 45662 | G1: 45669 | H1: 45676 | I1: 45683 | J1: 45690 | K1: 45697 | L1: 45704 | M1: 45711 | N1: 45718 | O1: 45725 | P1: 45732 | Q1: 45739
B2: Team 1 Venkatesh & Sunjeet (3 devs) | C2: 25 | P2: Regression/UAT | Q2: UAT
B3: Team 2 Minas & Manish (3 devs) | C3: 25
B4: Team 3 Minas & Vivek (2 devs) | C4: 20
B5: Team 4 Venkatesh & Amit (4 devs) | C5: 30
B6: Team 5 Minas & Laurence (2 devs) | C6: 25
B8: TOTAL | C8: =SUM(C2:C6) -> 125
B9: To deliver 1500 points (weeks) | C9: =1500/C8 -> 12
B10: To deliver 1500 points in 9 weeks (SP per week) | C10: =1500/9 -> 166.66667
B11: Team | C11: Epic | D11: Reduced Estimate | E11: # weeks | F11: Dependent On | G11: Extra Weeks
B12: Team 1 Venkatesh & Sunjeet | C12: Carbon (incl EPD, Auto Allocate) | D12: =SUM(D13:D20) -> 455 | E12: =D12/$C$2 -> 18.2 | G12: =SUM(E12)-COUNT($D$1:$O$1) -> 6.2
C13: Carbon Resource Library | D13: 55 | E13: =D13/$C$2 -> 2.2
C14: Carbon Item Library | D14: 85 | E14: =D14/$C$2 -> 3.4 | F14: Carbon Resource
C15: WBS Carbon & Calc | D15: 75 | E15: =D15/$C$2 -> 3 | F15: Carbon Libraries
C16: Baseline Assumption | D16: 40 | E16: =D16/$C$2 -> 1.6
C17: EPD | D17: 75 | E17: =D17/$C$2 -> 3
C18: Cost to Carbon Library | D18: 85 | E18: =D18/$C$2 -> 3.4 | F18: Carbon WBS
C19: Auto-Allocate | D19: 40 | E19: =D19/$C$2 -> 1.6 | F19: Carbon Libraries
C20: Carbon Reports | D20: - | E20: -
B22: Team 2 Minas & Manish | C22: Inflation | D22: 41 | E22: =D22/$C$3 -> 1.64 | G22: =SUM(E22:E26)-COUNT($D$1:$O$1) -> 2.44
C23: LTA | D23: 180 | E23: =D23/$C$3 -> 7.2 | F23: Carbon WBS
C24: Star Rates | D24: 60 | E24: =D24/$C$6 -> 2.4
C25: Contractor Fee Library | D25: 80 | E25: =D25/$C$6 -> 3.2 | F25: IFT?
B27: Team 3 Minas & Vivek | C27: Reporting Foundation Admin | D27: 19 | E27: =D27/$C$4 -> 0.95 | G27: =SUM(E27:E33)-COUNT($D$1:$O$1) -> -1.7
C28: Portfolio/Programme Risk | D28: 60 | E28: =D28/$C$4 -> 3
C29: AR and O&M fixed reports | D29: 47 | E29: =D29/$C$4 -> 2.35 | F29: Carbon & Reporting Foundation Admin
C30: CCESS | D30: 5 | E30: =D30/$C$4 -> 0.25 | F30: Carbon & Reporting Foundation Admin
C31: Carbon Reports | D31: 40 | E31: =D31/$C$4 -> 2 | F31: Carbon
C32: Workflow | D32: 35 | E32: =D32/$C$4 -> 1.75
B34: Team 4 Venkatesh & Amit | C34: Supply Chain - Interim Forecasting Tool | D34: 200 | E34: =D34/$C$5 -> 6.6666667 | F34: Carbon WBS | G34: =SUM(E34:E36)-COUNT($D$1:$O$1) -> 1.8333333
C35: TPE | D35: 215 | E35: =D35/$C$5 -> 7.1666667
B37: Team 5 Minas & Laurence | C37: Audit Log | D37: 11 | E37: =D37/$C$6 -> 0.44 | G37: =SUM(E37:E41)-COUNT($D$1:$O$1) -> -0.36
C38: System Access | D38: 40 | E38: =D38/$C$6 -> 1.6
C39: Calculators/Cost Models | D39: 20 | E39: =D39/$C$6 -> 0.8
C40: Comparator | D40: 120 | E40: =D40/$C$3 -> 4.8 | F40: Carbon WBS
C41: Scenario Analysis | D41: 100 | E41: =D41/$C$3 -> 4 | F41: Comparator
B43: Work Streams | D43: Reduced Estimate | E43: Team
B44: Dashboards (Power BI) | D44: 40 | E44: Jonny?
B45: WBS Tags and Custom Fields | D45: Need Estimate | E45: ?

Sheet MVP Meetings
B1: Topic | C1: Owner | D1: Meeting (UK timezone) | E1: Meeting (AU timezone) | F1: Notes
B2: EPD/Cost to Carbon Factor | C2: Venkatesh | D2: Tue 23rd Dec 10PM-11PM | E2: Wed 24th Dec 9AM-10AM | F2: Meeting done
B3: LTA | C3: Minas | D3: Wed 24th Dec 8AM-9:30AM | E3: Wed24th Dec 7PM-8:30PM | F3: Meeting done
B4: TPE & Auto Allocate (Cost & Carbon) | C4: Venkatesh | D4: Sun 28th Dec 10PM-11:30PM | E4: Mon 29th Dec 9AM-10:30AM | F4: Meeting done
B5: Scenario Analysis (Chapter 7) | C5: Minas | D5: Mon 29th Dec 7AM-8:30AM | E5: Mon 29th Dec 6PM-7:30PM
B6: Carbon Reports | C6: Minas
B9: Supply Chain - Interim Forecasting Tool (incl EPD) | C9: Venkatesh | D9: N/A | E9: N/A | F9: Venkatesh needs meeting with NH
B10: Dashboards (Power BI) | C10: Minas
B11: Comparator | C11: Minas
B12: Workflow | C12: Minas
B13: Tasks | C13: Minas
B14: Calculators/Cost Models (Chapter 10) | C14: Minas
B15: Star Rates | C15: Minas
B16: Contractor Fee Library | C16: Minas
D18: UK | E18: AU | F18: Status | G18: Topic
B19: Mark's avail. | D19: Wed 24th Dec UK morning | E19: Wed 24th AU evening | F19: Taken | G19: LTA
D20: Sat 27th Dec 7AM-9AM | E20: Sat 27th Dec 6PM-8PM | F20: X
D21: Sun 28th Dec 7AM-9AM | E21: Sun 28th Dec 6PM-8PM | F21: X
D22: Sun 28th Dec 10PM-11:30PM | E22: Mon 29th Dec 9AM-10:30AM | F22: Taken | G22: TPE & Auto Allocate (Cost & Carbon)
D23: Mon 29th Dec 7AM-9AM | E23: Mon 29th Dec 6PM-8PM | F23: Taken | G23: Scenario Analysis (Chapter 7)
D24: Mon 29th Dec 10PM-11:30PM | E24: Tue 30th Dec 9AM-10:30AM | F24: After MVP deadline (Mon 29th)
D25: Fri 2nd Jan UK morning | E25: Fri 2nd Jan AU evening | F25: After MVP deadline (Mon 29th)

Sheet Action Log
A1: ID | B1: Action | C1: Owner | D1: Raised Date | E1: Due Date / RAG | F1: Status
A3: A06 | B3: Finalise onboarding plan for 4 additional engineers chase profiles and shortlist | C3: Jerome | D3: 46027 | E3: 46031 | F3: In progress
A5: A26 | B5: Continue monitoring NH PRD sign-off behaviour and flag governance risk early | C5: Richard | D5: 46029 | E5: Ongoing | F5: Open
A7: A32 | B7: Risk around TPE and the amount if work to be done in the last Sprint | C7: Richard/Jerome | D7: 46068 | E7: 46068 | F7: In progress
A9: A33 | B9: Capacity / Velocity Concerns | C9: Richard/Jerome | D9: 46068 | E9: 46068 | F9: In progress

Sheet Current Defects
A1: Condition | D1: Status
A2: P1 > 0 | D2: 🔴 Escalation
A3: P1 = 0 AND Open defects ↑ for 2+ days | D3: 🟠 Watch
A4: Open defects ↓ OR steady & closures happening | D4: 🟢 Stable
A6: Release 1D | H6: Release 2A
A7: Date | B7: Raised by NH | C7: No P1's | D7: Total Open Defects | E7: Total Closed Today | F7: Daily Status | H7: Date | I7: No P1's | J7: Total No Defects | K7: Total Closed Today | L7: Daily Status
A8: 14/01/2026 | B8: 0 | C8: 0 | D8: 27 | E8: 2 | F8: 🟢 Stable | H8: 14/01/2026
A9: 15/01/2026 | B9: 0 | C9: 0 | D9: 27 | E9: 0 | F9: 🟢 Stable | H9: 15/01/2026 | I9: 0 | J9: 0 | K9: 0 | L9: 🟢 Stable
A10: 16/01/2026 | B10: 0 | C10: 0 | D10: 24 | E10: 3 | F10: 🟢 Stable | H10: 16/01/2026 | I10: 0 | J10: 0 | K10: 0 | L10: 🟢 Stable
A11: 17/01/2026 | H11: 17/01/2026
A12: 18/01/2026 | H12: 18/01/2026
A13: 19/01/2026 | B13: 0 | C13: 0 | D13: 23 | E13: 1 | F13: 🟢 Stable | H13: 19/01/2026 | I13: 0 | J13: 0 | K13: 0 | L13: 🟢 Stable
A14: 20/01/2026 | B14: 0 | C14: 0 | D14: 18 | E14: 5 | F14: 🟢 Stable | H14: 20/01/2026 | I14: 0 | J14: 0 | K14: 0 | L14: 🟢 Stable
A15: 21/01/2026 | B15: 0 | C15: 0 | D15: 16 | E15: 2 | F15: 🟢 Stable | H15: 21/01/2026 | I15: 0 | J15: 0 | K15: 0 | L15: 🟢 Stable
A16: 22/01/2026 | B16: 0 | C16: 0 | D16: 15 | E16: 1 | F16: 🟢 Stable | H16: 22/01/2026 | I16: 0 | J16: 0 | K16: 0 | L16: 🟢 Stable
A17: 23/01/2026 | B17: 0 | C17: 0 | D17: 13 | E17: 0 | F17: 🟢 Stable | H17: 23/01/2026 | I17: 0 | J17: 0 | K17: 0 | L17: 🟢 Stable
A18: 24/01/2026 | H18: 24/01/2026
A19: 25/01/2026 | H19: 25/01/2026
A20: 26/01/2026 | B20: 0 | C20: 0 | D20: 13 | E20: 0 | F20: 🟢 Stable | H20: 26/01/2026 | I20: 0 | J20: 0 | K20: 0 | L20: 🟢 Stable
A21: 27/01/2026 | B21: TBC | C21: 0 | D21: 11 | E21: 2 | F21: 🟢 Stable | H21: 27/01/2026 | I21: 0 | J21: 0 | K21: 0 | L21: 🟢 Stable
A22: 28/01/2026 | H22: 28/01/2026
A23: 29/01/2026 | H23: 29/01/2026
A24: 30/01/2026 | H24: 30/01/2026
A25: 31/01/2026 | H25: 31/01/2026
A26: 01/02/2026 | H26: 01/02/2026
A42: Master R1D Defect View - BMJIRA

Sheet Stage Gate Tracker
A1: Gate | B1: Owner | C1: Rationale | D1: Pass Criteria (Evidence Required) | E1: SPRINT 35 | F1: Carbon Resource Library | G1: Carbon Item Library | H1: System Access | I1: Audit Log | J1: WBS Tags and Custom Fields | K1: SPRINT 36 | L1: Long-Term Appraisal | M1: Cost to Carbon Library | N1: Portfolio/Programme Risk | O1: WBS Carbon & Calc | P1: Comparator | Q1: SPRINT 37 | R1: Star Rates | S1: Inflation | T1: AR and O&M fixed reports | U1: EPD | V1: Workflow | W1: Auto-Allocate | X1: Interim Forecasting Tool (incl EPD) | Y1: Carbon Reports | Z1: SPRINT 38 | AA1: Scenario Analysis (Chapter 7) | AB1: TPE | AC1: Dashboards (Power BI) | AD1: Reporting Foundation Admin
A2: SCOPE REFINEMENT
A3: 1. Individual PRDs Drafted | B3: Minas | C3: Ensures scope and requirements are explicit before design and build begin, avoiding downstream rework and ambiguity. | F3: Sprint 35 | G3: Sprint 35 | H3: Sprint 35 | I3: Sprint 35 | J3: Sprint 35 | L3: Sprint 36+37 | M3: Sprint 36 | N3: Sprint 36 | O3: Sprint 36+37 | P3: Sprint 36+37 | R3: Sprint 38 | S3: Sprint 38 | T3: Sprint 38 | U3: Sprint 38 | V3: Sprint 38 | W3: Sprint 38 | X3: Sprint 38+39 | Y3: Sprint 38 | AA3: Sprint 39 | AB3: Sprint 39 | AC3: Sprint 39 | AD3: Sprint 39
D4: • PRDs drafted for each of the MVP epics | F4: 46015 | G4: 46015 | H4: Done | I4: 46031 | J4: Done | L4: 46003 | M4: 46015 | N4: 46003 | O4: 46015 | P4: 46003 | R4: 46059 | S4: Done | T4: Done | U4: 46015 | V4: 46008 | W4: 46015 | X4: 46031 | Y4: No PRD Req | AA4: 46045 | AB4: 46052 | AC4: 46031 | AD4: Done
D5: • Functional requirements prioritised (Must / Should / Deferred) | F5: 46015 | G5: 46015 | H5: Done | I5: 46031 | J5: Done | L5: 46003 | M5: 46015 | N5: 46003 | O5: 46015 | P5: 46003 | R5: 46059 | S5: Done | T5: Done | U5: 46015 | V5: 46008 | W5: 46015 | X5: 46031 | Y5: No PRD Req | AA5: 46045 | AB5: 46052 | AC5: 46031 | AD5: Done
D6: • In-scope vs out-of-scope clearly defined | F6: 46015 | G6: 46015 | H6: Done | I6: 46031 | J6: Done | L6: 46003 | M6: 46015 | N6: 46003 | O6: 46015 | P6: 46003 | R6: 46059 | S6: Done | T6: Done | U6: 46015 | V6: 46008 | W6: 46015 | X6: 46031 | Y6: No PRD Req | AA6: 46045 | AB6: 46052 | AC6: 46031 | AD6: Done
D7: • Dependencies and assumptions explicitly documented | F7: 46015 | G7: 46015 | H7: Done | I7: 46031 | J7: Done | L7: 46003 | M7: 46015 | N7: 46003 | O7: 46015 | P7: 46003 | R7: 46059 | S7: Done | T7: Done | U7: 46015 | V7: 46008 | W7: 46015 | X7: 46031 | Y7: No PRD Req | AA7: 46045 | AB7: 46052 | AC7: 46031 | AD7: Done
A8: 2. PRDs Reviewed & Signed Off (NH) | B8: Richard | C8: Confirms shared understanding and agreement with NH to prevent late scope disputes or rework. | D8: • NH review completed | F8: 46030 | G8: 46030 | H8: Done | I8: 46038 | J8: Done | L8: 46038 | M8: 46038 | N8: 46038 | O8: 46030 | P8: 46043 | R8: 44968 | S8: Done | T8: Done | U8: 46030 | V8: 46030 | W8: 46038 | X8: 46038 | Y8: N/A | AA8: 46052 | AB8: 46059 | AC8: 46036 | AD8: Done
D9: • Explicit NH sign-off received | F9: N/A | G9: N/A | H9: N/A | I9: N/A | J9: N/A | L9: N/A | M9: N/A | N9: N/A | O9: N/A | P9: N/A | R9: N/A | S9: N/A | T9: N/A | U9: N/A | V9: N/A | W9: N/A | X9: N/A | Y9: N/A | AA9: N/A | AB9: N/A | AC9: N/A | AD9: N/A
D10: • No open scope alignment questions | F10: 46031 | G10: 46031 | H10: Done | I10: 46038 | J10: Done | L10: 46045 | M10: =M8+2 -> 46040 | N10: 46040 | O10: 46031 | P10: 46045 | R10: 44968 | S10: Done | T10: Done | U10: 46031 | V10: 46031 | W10: =W8+2 -> 46040 | X10: 46038 | Y10: N/A | AA10: 46052 | AB10: 46059 | AC10: 46038 | AD10: Done
D11: • Any gaps documented, escalated and resolved | F11: 46031 | G11: 46031 | H11: Done | I11: 46038 | J11: Done | L11: 46045 | M11: =M10 -> 46040 | N11: 46040 | O11: 46031 | P11: 46045 | R11: 44968 | S11: Done | T11: Done | U11: 46031 | V11: 46031 | W11: =W10 -> 46040 | X11: 46038 | Y11: N/A | AA11: 46052 | AB11: 46059 | AC11: 46038 | AD11: Done
A12: DESIGN STAGES
A13: 3. UX/UI Designs Completed | B13: Richard (coordination) | C13: Prevents design churn during development and ensures build teams are working from stable designs. | D13: • UX/UI designs completed for all in-scope MVP flows | F13: 46031 | G13: 46031 | H13: Done | I13: Done | J13: Done | L13: 46052 | M13: 46045 | N13: 46045 | O13: 46038 | P13: 46045 | R13: 44970 | S13: Done | T13: Done | U13: 46045 | V13: 46042 | W13: 46045 | X13: 46045 | Y13: 46059 | AA13: 46059 | AB13: 46066 | AC13: 46065 | AD13: Done
D14: • Designs reviewed and accepted internally | F14: 46031 | G14: 46031 | H14: Done | I14: Done | J14: Done | L14: 46052 | M14: 46045 | N14: 46045 | O14: 46038 | P14: 46045 | R14: 44970 | S14: Done | T14: Done | U14: 46045 | V14: 46042 | W14: 46045 | X14: 46045 | Y14: 46059 | AA14: 46059 | AB14: 46066 | AC14: 46065 | AD14: Done
D15: • Ownership agreed (Vigo vs in-house) | F15: 46031 | G15: 46031 | H15: Done | I15: Done | J15: Done | L15: 46052 | M15: 46045 | N15: 46045 | O15: 46038 | P15: 46045 | R15: 44970 | S15: Done | T15: Done | U15: 46045 | V15: 46042 | W15: 46045 | X15: 46045 | Y15: 46059 | AA15: 46059 | AB15: 46066 | AC15: 46065 | AD15: Done
D16: • No critical design work outstanding for sprint execution | F16: 46031 | G16: 46031 | H16: Done | I16: Done | J16: Done | L16: 46052 | M16: 46045 | N16: 46045 | O16: 46038 | P16: 46045 | R16: 44970 | S16: Done | T16: Done | U16: 46045 | V16: 46042 | W16: 46045 | X16: 46045 | Y16: 46059 | AA16: 46059 | AB16: 46066 | AC16: 46065 | AD16: Done
A17: 4. Solution Architectures (SAs) Drafted | B17: Richard (coordination) | C17: Grounds delivery commitments in technical reality and surfaces assumptions, risks, and trade-offs early. | D17: • SAs drafted for each epic | F17: 46036 | G17: 46036 | H17: Done | I17: Done | J17: Done | L17: 46057 | M17: 46051 | N17: 46051 | O17: 46045 | P17: 46051 | R17: 44977 | S17: Done | T17: Done | U17: 45686 | V17: 46048 | W17: 45686 | X17: 45686 | Y17: 46065 | AA17: 46066 | AB17: 46073 | AC17: 46065 | AD17: Done
D18: • Architecture simplified to MVP | F18: 46036 | G18: 46036 | H18: Done | I18: Done | J18: Done | L18: 46057 | M18: 46051 | N18: 46051 | O18: 46045 | P18: 46051 | R18: 44977 | S18: Done | T18: Done | U18: 45686 | V18: 46048 | W18: 45686 | X18: 45686 | Y18: 46065 | AA18: 46066 | AB18: 46073 | AC18: 46065 | AD18: Done
D19: • Technical assumptions and risks explicit | F19: 46036 | G19: 46036 | H19: Done | I19: Done | J19: Done | L19: 46057 | M19: 46051 | N19: 46051 | O19: 46045 | P19: 46051 | R19: 44977 | S19: Done | T19: Done | U19: 45686 | V19: 46048 | W19: 45686 | X19: 45686 | Y19: 46065 | AA19: 46066 | AB19: 46073 | AC19: 46065 | AD19: Done
D20: • Key trade-offs documented | F20: 46036 | G20: 46036 | H20: Done | I20: Done | J20: Done | L20: 46057 | M20: 46051 | N20: 46051 | O20: 46045 | P20: 46051 | R20: 44977 | S20: Done | T20: Done | U20: 45686 | V20: 46048 | W20: 45686 | X20: 45686 | Y20: 46065 | AA20: 46066 | AB20: 46073 | AC20: 46065 | AD20: Done
A21: 5. SAs Reviewed & Approved | B21: Jerome | C21: Locks technical feasibility before commitments are made and avoids late architectural rework. | D21: • SAs reviewed and approved | F21: 46038 | G21: 46038 | H21: Done | I21: Done | J21: Done | L21: 46059 | M21: 46051 | N21: 46051 | O21: 46045 | P21: 46051 | R21: 44980 | S21: Done | T21: Done | U21: 45686 | V21: 46048 | W21: 45686 | X21: 45686 | Y21: 46065 | AA21: 46066 | AB21: 46073 | AC21: 46065 | AD21: Done
D22: • Risks accepted or mitigated | F22: 46038 | G22: 46038 | H22: Done | I22: Done | J22: Done | L22: 46059 | M22: 46051 | N22: 46051 | O22: 46045 | P22: 46051 | R22: 44980 | S22: Done | T22: Done | U22: 45686 | V22: 46048 | W22: 45686 | X22: 45686 | Y22: 46065 | AA22: 46066 | AB22: 46073 | AC22: 46065 | AD22: Done
D23: • No unresolved feasibility questions | F23: 46038 | G23: 46038 | H23: Done | I23: Done | J23: Done | L23: 46059 | M23: 46051 | N23: 46051 | O23: 46045 | P23: 46051 | R23: 44980 | S23: Done | T23: Done | U23: 45686 | V23: 46048 | W23: 45686 | X23: 45686 | Y23: 46065 | AA23: 46066 | AB23: 46073 | AC23: 46065 | AD23: Done
D24: • Delivery implications understood by Delivery Manager | F24: 46038 | G24: 46038 | H24: Done | I24: Done | J24: Done | L24: 46059 | M24: 46051 | N24: 46051 | O24: 46045 | P24: 46051 | R24: 44980 | S24: Done | T24: Done | U24: 45686 | V24: 46048 | W24: 45686 | X24: 45686 | Y24: 46065 | AA24: 46066 | AB24: 46073 | AC24: 46065 | AD24: Done
A25: 6. Performance-Aware Design Approved | B25: Yoong | C25: Ensures design and architectural decisions do not inherently introduce performance, scalability, or data-related risk. | D25: • NFR defined (SLOs, throughput, user capacity) | F25: 46038 | G25: 46038 | H25: 46038 | I25: 46038 | J25: 46038
D26: • Scalability expectations, complexity and data volume projections documented | F26: 46038 | G26: 46038 | H26: 46038 | I26: 46038 | J26: 46038
D27: • Database schema optimised with indexing strategy | F27: 46038 | G27: 46038 | H27: 46038 | I27: 46038 | J27: 46038
D28: • APIs follows performance best practices | F28: 46038 | G28: 46038 | H28: 46038 | I28: 46038 | J28: 46038
A29: SPRINT SCHEDULING
A30: 7. Sprint Planning by Epic Completed | B30: Richard | C30: Ensures execution commitments are realistic, capacity-aligned, and dependency-aware before development starts. | D30: • Sprint plan complete by epic | F30: 46037 | G30: 46037 | H30: 46037 | I30: 46037 | J30: 46037 | L30: 46045 | M30: 46045 | N30: 46045 | O30: 46045 | P30: 46045 | R30: 46058 | S30: 46058 | T30: 46058 | U30: 46058 | V30: 46058 | W30: 46058 | X30: 46058 | Y30: 46065 | AA30: 46072 | AB30: 46072 | AC30: 46072 | AD30: 46072
D31: • Scope aligned to PRDs, UX/UI, and SAs | F31: 46037 | G31: 46037 | H31: 46037 | I31: 46037 | J31: 46037 | L31: 46045 | M31: 46045 | N31: 46045 | O31: 46045 | P31: 46045 | R31: 46058 | S31: 46058 | T31: 46058 | U31: 46058 | V31: 46058 | W31: 46058 | X31: 46058 | Y31: 46065 | AA31: 46072 | AB31: 46072 | AC31: 46072 | AD31: 46072
D32: • Dependencies explicit | F32: 46037 | G32: 46037 | H32: 46037 | I32: 46037 | J32: 46037 | L32: 46045 | M32: 46045 | N32: 46045 | O32: 46045 | P32: 46045 | R32: 46058 | S32: 46058 | T32: 46058 | U32: 46058 | V32: 46058 | W32: 46058 | X32: 46058 | Y32: 46065 | AA32: 46072 | AB32: 46072 | AC32: 46072 | AD32: 46072
D33: • Capacity and story points validated | F33: 46037 | G33: 46037 | H33: 46037 | I33: 46037 | J33: 46037 | L33: 46045 | M33: 46045 | N33: 46045 | O33: 46045 | P33: 46045 | R33: 46058 | S33: 46058 | T33: 46058 | U33: 46058 | V33: 46058 | W33: 46058 | X33: 46058 | Y33: 46065 | AA33: 46072 | AB33: 46072 | AC33: 46072 | AD33: 46072
A34: EXECUTION / DELIVERY
A35: 8. Development Complete & Code Integrated | B35: Richard | C35: Confirms committed sprint scope is fully built and integrated into the shared codebase, ready for formal QA/system testing. | D35: • All committed stories meet Definition of Done | F35: 46051 | G35: 46051 | H35: 46051 | I35: 46051 | J35: 46051 | L35: 46065 | M35: 46065 | N35: 46065 | O35: 46065 | P35: 46065 | R35: 46079 | S35: 46079 | T35: 46079 | U35: 46079 | V35: 46079 | W35: 46079 | X35: 46079 | Y35: 46079 | AA35: 46093 | AB35: 46093 | AC35: 46093 | AD35: 46093
D36: • Code merged to agreed branch with peer reviews completed | F36: 46051 | G36: 46051 | H36: 46051 | I36: 46051 | J36: 46051 | L36: 46065 | M36: 46065 | N36: 46065 | O36: 46065 | P36: 46065 | R36: 46079 | S36: 46079 | T36: 46079 | U36: 46079 | V36: 46079 | W36: 46079 | X36: 46079 | Y36: 46079 | AA36: 46093 | AB36: 46093 | AC36: 46093 | AD36: 46093
D37: • Sprint review completed and recorded | F37: 46051 | G37: 46051 | H37: 46051 | I37: 46051 | J37: 46051 | L37: 46065 | M37: 46065 | N37: 46065 | O37: 46065 | P37: 46065 | R37: 46079 | S37: 46079 | T37: 46079 | U37: 46079 | V37: 46079 | W37: 46079 | X37: 46079 | Y37: 46079 | AA37: 46093 | AB37: 46093 | AC37: 46093 | AD37: 46093
D38: • Integration complete across in-scope components | F38: 46051 | G38: 46051 | H38: 46051 | I38: 46051 | J38: 46051 | L38: 46065 | M38: 46065 | N38: 46065 | O38: 46065 | P38: 46065 | R38: 46079 | S38: 46079 | T38: 46079 | U38: 46079 | V38: 46079 | W38: 46079 | X38: 46079 | Y38: 46079 | AA38: 46093 | AB38: 46093 | AC38: 46093 | AD38: 46093
D39: • No gating integration issues preventing QA execution | F39: 46051 | G39: 46051 | H39: 46051 | I39: 46051 | J39: 46051 | L39: 46065 | M39: 46065 | N39: 46065 | O39: 46065 | P39: 46065 | R39: 46079 | S39: 46079 | T39: 46079 | U39: 46079 | V39: 46079 | W39: 46079 | X39: 46079 | Y39: 46079 | AA39: 46093 | AB39: 46093 | AC39: 46093 | AD39: 46093
A40: 9. System/QA Testing Completed | B40: Owner: Hema Oversight: Caroline | C40: Purpose: Validates functional correctness, system stability, and regression safety prior to Internal and NH UAT. Exit Evidence: QA summary report, defect status, QA sign-off | D40: • Unit testing completed for all in-scope BE/FE components | F40: 46051 | G40: 46051 | H40: 46051 | I40: 46051 | J40: 46051 | L40: 46065 | M40: 46065 | N40: 46065 | O40: 46065 | P40: 46065 | R40: 46079 | S40: 46079 | T40: 46079 | U40: 46079 | V40: 46079 | W40: 46079 | X40: 46079 | Y40: 46079 | AA40: 46093 | AB40: 46093 | AC40: 46093 | AD40: 46093
...

Sheet Work Plan V3
E1: Design Due Dates
B2: Workstream | C2: Owner | D2: NH upfront clarifcation needed? | E2: PRD (sent to NH for review) | F2: NH Sign Off | G2: VIGO: UI/UX Design | H2: Internal: UI/UX Design | I2: SA (Technical Solution Design) | J2: All Design Activities Due Date | K2: Dev Start | L2: Dev Finish | M2: SG1 | N2: SG2 | O2: SG3 | P2: SG4 | Q2: SG5 | R2: SG6 | S2: SG7 | T2: SG8 | U2: SG9 | V2: SG10 | W2: SG11 | X2: SG12 | Y2: Epics | Z2: Original Estimate | AA2: Updated Estimate | AB2: Priority | AC2: Allocated Team | AD2: Team Work Days (7 SP pd) | AE2: Team Work Days (8 SP pd) | AF2: 46024 | AG2: =AF2+1 -> 46025 | AH2: =AG2+1 -> 46026 | AI2: =AH2+1 -> 46027 | AJ2: =AI2+1 -> 46028 | AK2: =AJ2+1 -> 46029 | AL2: =AK2+1 -> 46030 | AM2: =AL2+1 -> 46031 | AN2: =AM2+1 -> 46032 | ... AS2: =AR2+1 -> 46037 | AT2: 46038 | AU2: =AT2+1 -> 46039 | AV2: =AU2+1 -> 46040 | AW2: =AV2+1 -> 46041 | AX2: =AW2+1 -> 46042 | AY2: =AX2+1 -> 46043 | AZ2: =AY2+1 -> 46044 | BA2: =AZ2+1 -> 46045 | BB2: =BA2+1 -> 46046 | ... DM2: =DL2+1 -> 46109 | DN2: =DL2+1 -> 46109 | DO2: =DN2+1 -> 46110 | DP2: =DO2+1 -> 46111 | DQ2: =DP2+1 -> 46112 | DR2: =DQ2+1 -> 46113 | DS2: =DR2+1 -> 46114 | DT2: Total
B3: Carbon Resource Library | C3: Venkatesh | E3: 46015 | F3: 46029 | G3: =F3+2 -> 46031 | H3: N/A | I3: =G3+7 -> 46038 | J3: =I3 -> 46038 | K3: Sprint 35 | L3: Sprint 35 | M3: √ | N3: √ | O3: √ | P3: √ | Q3: √ | R3: √ | S3: √ | Y3: https://benchmarkestimating.atlassian.net/browse/VER10-9428 | Z3: 575 | AA3: 55 | AB3: 1 | AC3: Team 1 | AD3: 7.8571429 | AE3: 6.875 | AT3: X | AW3: X | AX3: X | AY3: X | AZ3: X | BA3: X | BD3: X | BE3: X | BF3: X | DT3: =COUNTIF(AF3:DS3,"X") -> 9
B4: Carbon Item Library | C4: Venkatesh | E4: 46015 | F4: 46029 | G4: =F4+2 -> 46031 | H4: N/A | I4: =G4+7 -> 46038 | J4: =I4 -> 46038 | K4: Sprint 35 | L4: Sprint 35 | M4: √ | N4: √ | O4: √ | P4: √ | Q4: √ | R4: √ | S4: √ | Y4: https://benchmarkestimating.atlassian.net/browse/VER10-9373 | AA4: 85 | AB4: 2 | AC4: Team 4 | AD4: 12.142857 | AE4: 10.625 | AT4: X | AW4: X | AX4: X | AY4: X | AZ4: X | BA4: X | BD4: X | BE4: X | BF4: X | BG4: X | BH4: X | BK4: F | DT4: =COUNTIF(AF4:DS4,"X") -> 11
B5: Import / Export | C5: Venkatesh | E5: 46015 | F5: 46029 | G5: =F5+2 -> 46031 | H5: N/A | I5: =G5+7 -> 46038 | J5: =I5 -> 46038 | K5: Sprint 35 | L5: Sprint 35 | M5: √ | N5: √ | O5: √ | P5: √ | Q5: √ | R5: √ | S5: √ | AT5: X | AW5: X | AX5: X | AY5: X | AZ5: X | BA5: X | BD5: X | BE5: X | BF5: X | BG5: X | BH5: X | BK5: F
B6: WBS Carbon & Calc | C6: Venkatesh / Amit S. | E6: 46015 | F6: 46031 | G6: 46052 | H6: N/A | I6: 46052 | J6: =I6 -> 46052 | K6: Sprint 36 | L6: Sprint 37 | M6: √ | N6: √ | O6: √ | AA6: 75 | AB6: 4 | AC6: Team 4 | AD6: 10.714286 | AE6: 9.375 | BH6: X | BK6: X | BL6: X | BM6: X | BN6: X | BO6: X | BR6: X | BS6: X | BT6: X | BU6: X | BV6: X | BY6: F | DT6: =COUNTIF(AF6:DS6,"X") -> 11
B7: EPD | C7: Venkatesh / Sunjeet | E7: 46015 | F7: 46045 | G7: =F7+7 -> 46052 | H7: N/A | I7: =G7+6 -> 46058 | J7: =I7 -> 46058 | K7: Sprint 37 | L7: Sprint 37 | M7: √ | AA7: 75 | AB7: 5 | AC7: Team 1 | AD7: 10.714286 | AE7: 9.375 | BV7: X | BY7: X | BZ7: X | CA7: X | CB7: X | CC7: X | CF7: X | CG7: X | CH7: X | CI7: X | CJ7: X | CM7: X | CN7: X | CO7: X | CP7: F | DT7: =COUNTIF(AF7:DS7,"X") -> 14
B8: Cost to Carbon Library | C8: Venkatesh / Sunjeet | E8: 46015 | F8: 46045 | G8: 46059 | H8: N/A | I8: 46066 | J8: 46066 | K8: Sprint 37 | L8: Sprint 38 | M8: √ | N8: √ | AA8: 85 | AB8: 7 | AC8: Team 1 | AD8: 12.142857 | AE8: 10.625 | BH8: X | BK8: X | BL8: X | BM8: X | BN8: X | BO8: X | BR8: X | BS8: X | BT8: X | BU8: X | BV8: X | BY8: F | DT8: =COUNTIF(AF8:DS8,"X") -> 11
B9: Auto-Allocate | C9: Venkatesh / Amit S | E9: 46015 | F9: 46045 | G9: 46063 | H9: N/A | I9: 46066 | J9: 46066 | K9: Sprint 37 | L9: Sprint 37 | M9: √ | AA9: 40 | AB9: 6 | AC9: Team 4 | AD9: 5.7142857 | AE9: 5 | BH9: X | BK9: X | BL9: X | BM9: X | BN9: X | BO9: X | BR9: X | BS9: X | BT9: X | BU9: X | BV9: X | BY9: F | DT9: =COUNTIF(AF9:DS9,"X") -> 11
B10: Interim Forecasting Tool (incl EPD) | C10: Venkatesh | E10: Fri 12 Dec 2025 | F10: 46045 | G10: =F10+7 -> 46052 | H10: N/A | I10: =G10+7 -> 46059 | J10: =I10 -> 46059 | K10: Sprint 35 | L10: Sprint 39 | M10: √ | N10: √ | O10: √ | P10: √ | Q10: √ | R10: √ | S10: √ | Y10: VER10-8678, VER10-8680, VER10-8682, VER10-8858, VER10-8679, VER10-8921, VER10-9049, VER10-9128 | Z10: 177 | AA10: 200 | AB10: 1 | AC10: Team 4 | AD10: 28.571429 | AE10: 25 | AI10: X | AJ10: X | AK10: X | AL10: X | AM10: X | AP10: X | AQ10: X | AR10: X | AS10: X | AT10: X | AW10: X | AX10: X | AY10: X | AZ10: X | BA10: X | BD10: X | BE10: X | BF10: X | BG10: X | BH10: X | BK10: X | BL10: X | BM10: X | BN10: X | BO10: X | BR10: X | BS10: X | BT10: X | BU10: X | BV10: X | BY10: X | BZ10: X | CA10: X | CB10: X | CC10: X | CF10: X | CG10: X | CH10: X | CI10: X | CJ10: X | CM10: F | DT10: =COUNTIF(AF10:DS10,"X") -> 40
B11: Long-Term Appraisal | C11: Minas / Manish | E11: Fri 12 Dec 2025 | F11: 46045 | G11: =F11+7 -> 46052 | H11: N/A | I11: 46052 | J11: =I11 -> 46052 | K11: Sprint 36 | L11: Sprint 37 | M11: √ | N11: √ | Y11: VER10-9697, VER10-9698, VER10-9699, VER10-9700, VER10-9701, VER10-9702 | Z11: 260 | AA11: 180 | AB11: 4 | AC11: Team 2 | AD11: 25.714286 | AE11: 22.5 | BG11: X | BH11: X | BK11: X | BL11: X | BM11: X | BN11: X | BO11: X | BR11: X | BS11: X | BT11: X | BU11: X | BV11: X | BY11: X | BZ11: X | CA11: X | CB11: X | CC11: X | CF11: X | CG11: X | CH11: F | DT11: =COUNTIF(AF11:DS11,"X") -> 19
B12: Comparator | C12: Minas / Laurence | D12: Y | E12: Fri 12 Dec 2025 | F12: 46041 | G12: =F12+7 -> 46048 | H12: N/A | I12: 46052 | J12: =I12 -> 46052 | K12: Sprint 36 | L12: Sprint 37 | M12: √ | N12: √ | Y12: VER10-8953 | Z12: 120 | AA12: 120 | AB12: 4 | AC12: Team 5 | AD12: 17.142857 | AE12: 15 | BK12: X | BL12: X | BM12: X | BN12: X | BO12: X | BR12: X | BS12: X | BT12: X | BU12: X | BV12: X | BY12: F | DT12: =COUNTIF(AF12:DS12,"X") -> 10
B13: Carbon Reports | C13: Minas / Vivek | E13: 46031 | F13: =E13+7 -> 46038 | G13: N/A | H13: N/A | I13: 46066 | J13: 46066 | K13: Sprint 37 | L13: Sprint 38 | AA13: 40 | AC13: Team 3 | AD13: 5.7142857 | AE13: 5 | BV13: X | BY13: X | BZ13: X | CA13: X | CB13: X | CC13: X | CF13: X | CG13: X | CH13: X | CI13: X | CJ13: F | DT13: =COUNTIF(AF13:DS13,"X") -> 10
B14: Workflow | C14: Minas / Vivek | D14: Y | E14: Fri 12 Dec 2025 | F14: 46052 | G14: 46066 | H14: N/A | I14: =G14+7 -> 46073 | J14: =I14 -> 46073 | K14: Sprint 38 | L14: Sprint 38 | M14: √ | Y14: VER10-9028 | Z14: 35 | AA14: 35 | AB14: 5 | AC14: Team 3 | AD14: 5 | AE14: 4.375 | BV14: X | BY14: X | BZ14: X | CA14: X | CB14: X | CC14: X | CF14: X | CG14: X | CH14: X | CI14: X | CJ14: X | CM14: F | DT14: =COUNTIF(AF14:DS14,"X") -> 11
B15: Portfolio/Programme Risk | C15: Minas / Vivek | E15: Fri 12 Dec 2025 | F15: Mon 22 Dec 2025 | G15: 46052 | H15: N/A | I15: 46052 | J15: =I15 -> 46052 | K15: Sprint 36 | L15: Sprint 36 | M15: √ | N15: √ | O15: √ | Y15: VER10-9494 | Z15: 80 | AA15: 60 | AB15: 5 | AC15: Team 3 | AD15: 8.5714286 | AE15: 7.5 | BH15: X | BK15: X | BL15: X | BM15: X | BN15: X | BO15: X | BR15: X | BS15: X | BT15: X | BU15: X | BV15: X | BY15: F | DT15: =COUNTIF(AF15:DS15,"X") -> 11
B16: Calculators/Cost Models (Chapter 10) | C16: Minas | E16: Thu 18 Dec 2025 | F16: Fri 9 Jan 2025 | G16: N/A | H16: N/A | I16: 46045 | J16: =I16 -> 46045 | K16: Sprint 35 | L16: Sprint 35 | M16: √ | N16: √ | O16: √ | Y16: No Epic | Z16: 20 | AA16: 20 | AB16: 6 | AC16: Team 5 | AD16: 2.8571429 | AE16: 2.5 | AT16: X | AW16: X | AX16: X | AY16: X | AZ16: X | BA16: X | BD16: X | BE16: X | BF16: X | BG16: X | BH16: X | BK16: F | DT16: =COUNTIF(AF16:DS16,"X") -> 11
B17: Scenario Analysis (Chapter 7) | C17: Minas? (TBC) | E17: 46045 | F17: 46066 | G17: 46073 | H17: N/A | I17: 46080 | J17: =I17 -> 46080 | K17: Sprint 38 | L17: Sprint 39 | M17: √ | Y17: VER10-8958 | Z17: 140 | AA17: 100 | AB17: 5 | AC17: Team 3 | AD17: 14.285714 | AE17: 12.5 | CJ17: X | CM17: X | CN17: X | CO17: X | CP17: X | CQ17: X | CT17: X | CU17: X | CV17: X | CW17: X | CX17: F | DT17: =COUNTIF(AF17:DS17,"X") -> 10
B18: Star Rates | C18: Minas? (TBC) | E18: 46059 | F18: 46064 | G18: N/A | H18: 46066 | I18: 46066 | J18: =I18 -> 46066 | K18: Sprint 37 | L18: Sprint 37 | Y18: No Epic | Z18: 90 | AA18: 60 | AC18: Team 2 | AD18: 8.5714286 | AE18: 7.5 | BV18: X | BY18: X | BZ18: X | CA18: X | CB18: X | CC18: X | CF18: X | CG18: X | CH18: X | CI18: X | CJ18: X | CM18: F | DT18: =COUNTIF(AF18:DS18,"X") -> 11
B19: TPE | C19: Venkatesh | E19: 46052 | F19: 46059 | G19: 46073 | H19: N/A | I19: 46080 | J19: 46080 | K19: Sprint 38 | L19: Sprint 39 | Y19: VER10-9184 | Z19: 350 | AA19: 215 | AB19: 4 | AC19: Team 5 | AD19: 30.714286 | AE19: 26.875 | CJ19: X | CM19: X | CN19: X | CO19: X | CP19: X | CQ19: X | CT19: X | CU19: X | CV19: X | CW19: X | CX19: F | DT19: =COUNTIF(AF19:DS19,"X") -> 10
B20: Dashboards (Power BI) | C20: Minas | E20: 46031 | F20: N/A | G20: N/A | H20: N/A | I20: N/A | J20: N/A | K20: Sprint 38 | L20: Sprint 38 | M20: √ | Y20: No Epic | Z20: 40 | AA20: 40 | AB20: 2 | AC20: Dashboard Team | AD20: 5.7142857 | AE20: 5 | BV20: X | BY20: X | BZ20: X | CA20: X | CB20: X | CC20: X | CF20: X | CG20: X | CH20: X | CI20: X | CJ20: X | CM20: F | DT20: =COUNTIF(AF20:DS20,"X") -> 11
B21: Contractor Fee Library | C21: Minas | E21: 46066 | F21: 46071 | G21: N/A | H21: =E21+7 -> 46073 | I21: =H21+7 -> 46080 | J21: =I21 -> 46080 | K21: Sprint 38 | L21: Sprint 38 | Y21: VER10-9271 | Z21: 90 | AA21: 80 | AB21: 3 | AC21: Team 2 | AD21: 11.428571 | AE21: 10 | CJ21: X | CM21: X | CN21: X | CO21: X | CP21: X | CQ21: X | CT21: X | CU21: X | CV21: X | CW21: X | CX21: F | DT21: =COUNTIF(AF21:DS21,"X") -> 10
B22: System Access | C22: Minas | E22: 46031 | F22: =E22+7 -> 46038 | G22: N/A | H22: =F22+7 -> 46045 | I22: 46045 | J22: =I22 -> 46045 | K22: Sprint 35 | L22: Sprint 35 | Y22: VER10-8452 | Z22: 40 | AA22: 40 | AB22: 3 | AC22: Team 5 | AD22: 5.7142857 | AE22: 5 | AI22: X | AJ22: X | AK22: X | AL22: X | AM22: X | AP22: X | AQ22: X | AR22: X | AS22: X | AT22: X | AW22: X | AX22: X | AY22: X | AZ22: X | BA22: X | BD22: X | BE22: X | BF22: X | BG22: X | BH22: X | BK22: F | DT22: =COUNTIF(AF22:DS22,"X") -> 20
B23: Audit Log | C23: Minas | E23: Done | F23: Done | G23: Done | H23: 46045 | I23: =H23+6 -> 46051 | J23: =I23 -> 46051 | K23: Sprint 35 | L23: Sprint 35 | M23: √ | N23: √ | O23: √ | P23: √ | Q23: √ | R23: √ | S23: √ | Y23: VER10-8955, VER10-6972 | Z23: 10 | AA23: 11 | AC23: Team 5 | AD23: 1.5714286 | AE23: 1.375 | AT23: X | AW23: X | AX23: X | AY23: X | AZ23: X | BA23: X | BD23: X | BE23: X | BF23: X | BG23: X | BH23: X | BK23: F | DT23: =COUNTIF(AF23:DS23,"X") -> 11
B24: WBS Tags and Custom Fields | C24: Minas / Manish | E24: Done | F24: Done | G24: Done | H24: Done | I24: Done | J24: Done | K24: Sprint 36 | L24: Sprint 36 | M24: √ | N24: √ | O24: √ | P24: √ | Q24: √ | R24: √ | S24: √ | Y24: VER10-8916, VER10-8268 | Z24: 10 | AA24: 10 | AC24: Team 2 | AD24: 1.4285714 | AE24: 1.25 | AL24: X | AM24: F | AT24: X | AW24: X | AX24: X | AY24: X | AZ24: X | BA24: X | BD24: X | BE24: X | BF24: X | BG24: X | BH24: X | BK24: F | DT24: =COUNTIF(AF24:DS24,"X") -> 12
B25: Custom Field Filtering | C25: Minas | E25: Done | F25: Done | G25: Done | H25: Done | I25: Done | J25: Done | K25: Sprint 35 | L25: Sprint 35 | M25: √ | N25: √ | O25: √ | P25: √ | Q25: √ | R25: √ | S25: √ | BH25: X | BK25: X | BL25: X | BM25: X | BN25: X | BO25: X | BR25: X | BS25: X | BT25: X | BU25: X | BV25: X | BY25: F
B26: Reporting Foundation Admin | C26: Minas / Vivek | E26: Done | F26: Done | G26: Done | H26: Done | I26: Done | J26: Done | K26: Sprint 36 | L26: Sprint 36 | M26: √ | N26: √ | O26: √ | P26: √ | Q26: √ | R26: √ | S26: √ | Y26: VER10-8476 | Z26: 19 | AA26: 19 | AC26: Team 3 | AD26: 2.7142857 | AE26: 2.375 | AJ26: X | AK26: X | AL26: X | AM26: F | AT26: X | AW26: X | AX26: X | AY26: X | AZ26: X | BA26: X | BD26: X | BE26: X | BF26: X | BG26: X | BH26: X | BK26: F | DT26: =COUNTIF(AF26:DS26,"X") -> 14
B27: Inflation | C27: Minas | E27: Done | F27: Done | G27: Done | H27: Done | I27: Done | J27: Done | K27: Sprint 37 | L27: Sprint 37 | M27: √ | N27: √ | O27: √ | P27: √ | Q27: √ | R27: √ | Y27: VER10-8903, VER10-8570 | Z27: 41 | AA27: 41 | AC27: Team 3 | AD27: 5.8571429 | AE27: 5.125 | AP27: X | AQ27: X | AR27: X | AS27: X | BH27: X | BK27: X | BL27: X | BM27: X | BN27: X | BO27: X | BR27: X | BS27: X | BT27: X | BU27: X | BV27: X | BY27: F | DT27: =COUNTIF(AF27:DS27,"X") -> 15
B28: AR and O&M fixed reports | C28: Minas | E28: Done | F28: Done | G28: Done | H28: Done | I28: Done | J28: Done | K28: Sprint 37 | L28: Sprint 37 | M28: √ | N28: √ | O28: √ | P28: √ | Q28: √ | R28: √ | Y28: VER10-7878, VER10-7879 | Z28: 47 | AA28: 47 | AC28: Team 3 | AD28: 6.7142857 | AE28: 5.875 | AM28: X | AP28: X | AQ28: X | AR28: X | AS28: X | BV28: X | BY28: X | BZ28: X | CA28: X | CB28: X | CC28: X | CF28: X | CG28: X | CH28: X | CI28: X | CJ28: X | CM28: F | DT28: =COUNTIF(AF28:DS28,"X") -> 16
B29: CCESS | C29: Minas | E29: Done | F29: Done | G29: Done | H29: Done | I29: Done | J29: Done | K29: Sprint 37 | L29: Sprint 37 | M29: √ | N29: √ | O29: √ | P29: √ | Y29: VER10-6966 | Z29: 5 | AA29: 5 | AC29: Team 3 | AD29: 0.71428571 | AE29: 0.625 | BV29: X | BY29: X | BZ29: X | CA29: X | CB29: X | CC29: X | CF29: X | CG29: X | CH29: X | CI29: X | CJ29: X | CM29: F | DT29: =COUNTIF(AF29:DS29,"X") -> 11
Z30: =SUM(Z3:Z29) -> 2149 | AA30: =SUM(AA3:AA29) -> 1738 | AB30: =SUM(AA3:AB29) -> 1805 | AD30: =SUM(AD3:AD29) -> 248.28571 | AE30: =SUM(AE3:AE29) -> 217.25 | AF30: =COUNTIF(AF3:AF29, "X") -> 0 | AG30: =COUNTIF(AG3:AG29, "X") -> 0 | AH30: =COUNTIF(AH3:AH29, "X") -> 0 | AI30: =COUNTIF(AI3:AI29, "X") -> 2 | AJ30: =COUNTIF(AJ3:AJ29, "X") -> 3 | AK30: =COUNTIF(AK3:AK29, "X") -> 3 | AL30: =COUNTIF(AL3:AL29, "X") -> 4 | AM30: =COUNTIF(AM3:AM29, "X") -> 3 | ... DS30: =COUNTIF(DS3:DS29, "X") -> 0 | DT30: =SUM(DT3:DT29) -> 330
B32: Key | C32: For this week | AC32: Team 1 | AF32: =COUNTIFS($AC$3:$AC$29, $AC32, AF$3:AF$29,"X") -> 0 | AG32: =COUNTIFS($AC$3:$AC$29, $AC32, AG$3:AG$29,"X") -> 0 | AH32: =COUNTIFS($AC$3:$AC$29, $AC32, AH$3:AH$29,"X") -> 0 | AI32: =COUNTIFS($AC$3:$AC$29, $AC32, AI$3:AI$29,"X") -> 0 | AJ32: =COUNTIFS($AC$3:$AC$29, $AC32, AJ$3:AJ$29,"X") -> 0 | AK32: =COUNTIFS($AC$3:$AC$29, $AC32, AK$3:AK$29,"X") -> 0 | AL32: =COUNTIFS($AC$3:$AC$29, $AC32, AL$3:AL$29,"X") -> 0 | AM32: =COUNTIFS($AC$3:$AC$29, $AC32, AM$3:AM$29,"X") -> 0 | ... DS32: =COUNTIFS($AC$3:$AC$29, $AC32, DS$3:DS$29,"X") -> 0 | DT32: =SUMIFS($DT$3:$DT$29, $AC$3:$AC$29, AC32) -> 25
C33: Complete | AC33: Team 2 | AF33: =COUNTIFS($AC$3:$AC$29, $AC33, AF$3:AF$29,"X") -> 0 | AG33: =COUNTIFS($AC$3:$AC$29, $AC33, AG$3:AG$29,"X") -> 0 | AH33: =COUNTIFS($AC$3:$AC$29, $AC33, AH$3:AH$29,"X") -> 0 | AI33: =COUNTIFS($AC$3:$AC$29, $AC33, AI$3:AI$29,"X") -> 0 | AJ33: =COUNTIFS($AC$3:$AC$29, $AC33, AJ$3:AJ$29,"X") -> 0 | AK33: =COUNTIFS($AC$3:$AC$29, $AC33, AK$3:AK$29,"X") -> 0 | AL33: =COUNTIFS($AC$3:$AC$29, $AC33, AL$3:AL$29,"X") -> 1 | AM33: =COUNTIFS($AC$3:$AC$29, $AC33, AM$3:AM$29,"X") -> 0 | ... DS33: =COUNTIFS($AC$3:$AC$29, $AC33, DS$3:DS$29,"X") -> 0 | DT33: =SUMIFS($DT$3:$DT$29, $AC$3:$AC$29, AC33) -> 52
C34: At risk (Mitigation) | AC34: Team 3 | AF34: =COUNTIFS($AC$3:$AC$29, $AC34, AF$3:AF$29,"X") -> 0 | AG34: =COUNTIFS($AC$3:$AC$29, $AC34, AG$3:AG$29,"X") -> 0 | AH34: =COUNTIFS($AC$3:$AC$29, $AC34, AH$3:AH$29,"X") -> 0 | AI34: =COUNTIFS($AC$3:$AC$29, $AC34, AI$3:AI$29,"X") -> 0 | AJ34: =COUNTIFS($AC$3:$AC$29, $AC34, AJ$3:AJ$29,"X") -> 1 | AK34: =COUNTIFS($AC$3:$AC$29, $AC34, AK$3:AK$29,"X") -> 1 | AL34: =COUNTIFS($AC$3:$AC$29, $AC34, AL$3:AL$29,"X") -> 1 | AM34: =COUNTIFS($AC$3:$AC$29, $AC34, AM$3:AM$29,"X") -> 1 | ... DS34: =COUNTIFS($AC$3:$AC$29, $AC34, DS$3:DS$29,"X") -> 0 | DT34: =SUMIFS($DT$3:$DT$29, $AC$3:$AC$29, AC34) -> 98
C35: Blocked/Late | AC35: Team 4 | AF35: =COUNTIFS($AC$3:$AC$29, $AC35, AF$3:AF$29,"X") -> 0 | AG35: =COUNTIFS($AC$3:$AC$29, $AC35, AG$3:AG$29,"X") -> 0 | AH35: =COUNTIFS($AC$3:$AC$29, $AC35, AH$3:AH$29,"X") -> 0 | AI35: =COUNTIFS($AC$3:$AC$29, $AC35, AI$3:AI$29,"X") -> 1 | AJ35: =COUNTIFS($AC$3:$AC$29, $AC35, AJ$3:AJ$29,"X") -> 1 | AK35: =COUNTIFS($AC$3:$AC$29, $AC35, AK$3:AK$29,"X") -> 1 | AL35: =COUNTIFS($AC$3:$AC$29, $AC35, AL$3:AL$29,"X") -> 1 | AM35: =COUNTIFS($AC$3:$AC$29, $AC35, AM$3:AM$29,"X") -> 1 | ... DS35: =COUNTIFS($AC$3:$AC$29, $AC35, DS$3:DS$29,"X") -> 0 | DT35: =SUMIFS($DT$3:$DT$29, $AC$3:$AC$29, AC35) -> 73
AC36: Team 5 | AF36: =COUNTIFS($AC$3:$AC$29, $AC36, AF$3:AF$29,"X") -> 0 | AG36: =COUNTIFS($AC$3:$AC$29, $AC36, AG$3:AG$29,"X") -> 0 | AH36: =COUNTIFS($AC$3:$AC$29, $AC36, AH$3:AH$29,"X") -> 0 | AI36: =COUNTIFS($AC$3:$AC$29, $AC36, AI$3:AI$29,"X") -> 1 | AJ36: =COUNTIFS($AC$3:$AC$29, $AC36, AJ$3:AJ$29,"X") -> 1 | AK36: =COUNTIFS($AC$3:$AC$29, $AC36, AK$3:AK$29,"X") -> 1 | AL36: =COUNTIFS($AC$3:$AC$29, $AC36, AL$3:AL$29,"X") -> 1 | AM36: =COUNTIFS($AC$3:$AC$29, $AC36, AM$3:AM$29,"X") -> 1 | ... DS36: =COUNTIFS($AC$3:$AC$29, $AC36, DS$3:DS$29,"X") -> 0 | DT36: =SUMIFS($DT$3:$DT$29, $AC$3:$AC$29, AC36) -> 62
B37: Sprint Dates | C37: Starts | E37: Ends | AC37: Total | AF37: =SUM(AF32:AF36) -> 0 | AG37: =SUM(AG32:AG36) -> 0 | AH37: =SUM(AH32:AH36) -> 0 | AI37: =SUM(AI32:AI36) -> 2 | AJ37: =SUM(AJ32:AJ36) -> 3 | AK37: =SUM(AK32:AK36) -> 3 | AL37: =SUM(AL32:AL36) -> 4 | AM37: =SUM(AM32:AM36) -> 3 | ... DS37: =SUM(DS32:DS36) -> 0
B38: Sprint 35 | C38: 19/01/26 | E38: 02/02/26
B39: Sprint 36 | C39: 02/02/26 | E39: 16/02/26
B40: Sprint 37 | C40: 16/02/26 | E40: 02/03/26
B41: Sprint 38 | C41: 02/03/26 | E41: 16/03/26
...

Sheet ESCALATIONS
A1: Escalations Week Commencing 26-Jan
A2: Escalation Date | B2: Escalation | C2: Raised by | D2: Stage Gate | E2: Escalation Owner | F2: Due Date | G2: RAG | H2: Resolved Date | I2: Commentary
A3: Week Commencing (12th) | B3: PRD Review - IFT | C3: Richard | D3: SG2 - NH Sign-Off | E3: Richard | F3: 16/01/2026 | H3: 23/01/2026 | I3: NH review completed / Sprint 39 to be added so replan can happen
A5: 22/01/2026 | B5: SA - Import/Export | C5: Richard | D5: SG5 -SA Review | E5: Yoong | I5: No import/export in SG tracker?
A6: 22/01/2026 | B6: SA - Cost Models/Calculators | C6: Richard | D6: SG5 -SA Review | E6: Jerome | I6: No Cost models/Calcs in SG tracker?
A8: 27/01/2026 | B8: LTA UI/UX + SA at risk for 30/01/2026 | C8: Minas | D8: SG3 + SG4 | E8: Richard
A9: 27/01/2026 | B9: Comparator UI/UX at risk | C9: Minas | D9: SG3 | E9: Richard
A10: 27/01/2026 | B10: Review of Sprint Plan / Sequencing of PRD/SA etc | C10: Minas | E10: Richard
A18: 🟢 Green – On track / no dependency risk
A19: 🟡 Amber – Dependency, waiting on decision/input
A20: 🔴 Red – Missed date, blocking delivery, escalation needed

Sheet ARCHIVE >>

Sheet Work Plan
E1: Design Due Dates
B2: Workstream | C2: Owner | D2: NH upfront clarifcation needed? | E2: PRD (sent to NH for review) | F2: NH Sign Off | G2: VIGO: UI/UX Design | H2: Internal: UI/UX Design | I2: SA (Technical Solution Design) | J2: All Design Activities Due Date | K2: Epics | L2: Original Estimate | M2: Updated Estimate | N2: Priority | O2: Allocated Team | P2: Team Days (current 25SP/d) | Q2: Team Days (Uplifted 30SP/d) | R2: 46024 | S2: =R2+1 -> 46025 | T2: =S2+1 -> 46026 | U2: =T2+1 -> 46027 | V2: =U2+1 -> 46028 | W2: =V2+1 -> 46029 | X2: =W2+1 -> 46030 | Y2: =X2+1 -> 46031 | Z2: =Y2+1 -> 46032 | ... CL2: =CK2+1 -> 46096 | CM2: Total
B3: Estimate Build – Carbon (incl. EPD) | C3: Venkatesh& Minas | E3: 46015 | J3: =I3 | K3: VER10-8954, VER10-9428, VER10-9464, VER10-9527, VER10-9523 | L3: 575 | M3: =SUM(M4:M11) -> 495 | O3: 2 x Teams | P3: =SUM(M3:N3) / Capacity!$B$2 -> 70.714286 | Q3: =SUM(M3:N3)/(Capacity!$B$3*2) -> 30.9375 | CM3: =SUM(R3:BI3) -> 0
B4: Carbon Resource Library | C4: Venkatesh | E4: 46015 | F4: 46031 | M4: 55 | N4: 1 | O4: Team 1 | P4: =SUM(M4:N4) / Capacity!$B$2 -> 8 | Q4: =SUM(M4:N4)/Capacity!$B$3 -> 7 | Y4: X | AB4: X | AC4: X | AD4: X | AE4: X | AF4: X | AI4: X | AJ4: F | CM4: =COUNTIF(R4:CL4,"X") -> 7
B5: Carbon Item Library | C5: Venkatesh | E5: 46015 | F5: 46031 | M5: 85 | N5: 2 | O5: Team 4 | P5: =SUM(M5:N5) / Capacity!$B$2 -> 12.428571 | Q5: =SUM(M5:N5)/Capacity!$B$3 -> 10.875 | Y5: X | AB5: X | AC5: X | AD5: X | AE5: X | AF5: X | AI5: X | AJ5: X | AK5: X | AL5: X | AM5: X | AP5: UnLk | CM5: =COUNTIF(R5:CL5,"X") -> 11
B6: WBS Carbon & Calc | C6: Venkatesh | E6: 46015 | F6: 46031 | M6: 75 | N6: 4 | O6: Team 4 | P6: =SUM(M6:N6) / Capacity!$B$2 -> 11.285714 | Q6: =SUM(M6:N6)/Capacity!$B$3 -> 9.875 | AP6: X | AQ6: X | AR6: X | AS6: X | AT6: X | AW6: X | AX6: X | AY6: X | AZ6: X | BA6: X | BD6: UnLk | CM6: =COUNTIF(R6:CL6,"X") -> 10
B7: Baseline Assumption | C7: Venkatesh | E7: 46015 | F7: 46031 | M7: 40 | N7: 3 | O7: Team 1 | P7: =SUM(M7:N7) / Capacity!$B$2 -> 6.1428571 | Q7: =SUM(M7:N7)/Capacity!$B$3 -> 5.375 | AK7: X | AL7: X | AM7: X | AP7: X | AQ7: X | AR7: F | CM7: =COUNTIF(R7:CL7,"X") -> 5
B8: EPD | C8: Venkatesh | E8: 46015 | F8: 46031 | M8: 75 | N8: 5 | O8: Team 1 | P8: =SUM(M8:N8) / Capacity!$B$2 -> 11.428571 | Q8: =SUM(M8:N8)/Capacity!$B$3 -> 10 | AS8: X | AT8: X | AW8: X | AX8: X | AY8: X | AZ8: X | BA8: X | BD8: X | BE8: X | BF8: X | BG8: F | CM8: =COUNTIF(R8:CL8,"X") -> 10
B9: Cost to Carbon Library | C9: Venkatesh | E9: 46015 | F9: 46031 | M9: 85 | N9: 7 | O9: Team 1 | P9: =SUM(M9:N9) / Capacity!$B$2 -> 13.142857 | Q9: =SUM(M9:N9)/Capacity!$B$3 -> 11.5 | BH9: X | BK9: X | BL9: X | BM9: X | BN9: X | BO9: X | BR9: X | BS9: X | BT9: X | BU9: X | BV9: X | BY9: X | BZ9: F | CM9: =COUNTIF(R9:CL9,"X") -> 12
B10: Auto-Allocate | C10: Venkatesh | E10: 46015 | F10: 46031 | M10: 40 | N10: 6 | O10: Team 4 | P10: =SUM(M10:N10) / Capacity!$B$2 -> 6.5714286 | Q10: =SUM(M10:N10)/Capacity!$B$3 -> 5.75 | BE10: X | BF10: X | BG10: X | BH10: X | BK10: X | BL10: X | BM10: F | CM10: =COUNTIF(R10:CL10,"X") -> 6
B11: Carbon Reports | C11: MInas | E11: ? | F11: 46031 | M11: 40 | O11: Team 3 | P11: =SUM(M11:N11) / Capacity!$B$2 -> 5.7142857 | Q11: =SUM(M11:N11)/Capacity!$B$3 -> 5 | BR11: X | BS11: X | BT11: X | BU11: X | BV11: X | BY11: F | CM11: =COUNTIF(R11:CL11,"X") -> 5
B12: Interim Forecasting Tool (incl EPD) | C12: Venkatesh | E12: 46031 | F12: 46035 | G12: 46043 | H12: N/A | I12: =G12+7 -> 46050 | J12: =I12 -> 46050 | K12: VER10-8678, VER10-8680, VER10-8682, VER10-8858,, VER10-8679, VER10-8921, VER10-9049,, VER10-9128, | L12: 177 | M12: 200 | N12: 1 | O12: Team 4 | P12: =SUM(M12:N12) / Capacity!$B$2 -> 28.714286 | Q12: =SUM(M12:N12)/Capacity!$B$3 -> 25.125 | R12: X | U12: X | V12: X | W12: X | X12: X | BE12: X | BF12: X | BG12: X | BH12: X | BI12: X | BK12: X | BL12: X | BM12: X | BN12: X | BO12: X | BR12: X | BS12: X | BT12: X | BU12: X | BV12: X | BY12: X | BZ12: X | CA12: X | CB12: X | CC12: F | CM12: =COUNTIF(R12:CL12,"X") -> 24
B13: Long-Term Appraisal | C13: Funsho | E13: Fri 12 Dec 2025 (Done on time) | F13: 46008 | G13: 46037 | H13: N/A | I13: =G13+7 -> 46044 | J13: =I13 -> 46044 | K13: VER10-8565 | L13: 260 | M13: 180 | N13: 4 | O13: Team 2 | P13: =SUM(M13:N13) / Capacity!$B$2 -> 26.285714 | Q13: =SUM(M13:N13)/(Capacity!$B$3*2) -> 11.5 | BH13: X | BK13: X | BL13: X | BM13: X | BN13: X | BO13: X | BR13: X | BS13: X | BT13: X | BU13: X | BV13: X | BY13: X | BZ13: F | CM13: =COUNTIF(R13:CL13,"X") -> 12
B14: Comparator | C14: Funsho | D14: Y | E14: 19/12/2025 (Done on time) | F14: 46015 | G14: 46037 | H14: N/A | I14: =G14+7 -> 46044 | J14: =I14 -> 46044 | K14: VER10-8953 | L14: 120 | M14: 120 | N14: 4 | O14: Team 5 | P14: =SUM(M14:N14) / Capacity!$B$2 -> 17.714286 | Q14: =SUM(M14:N14)/Capacity!$B$3 -> 15.5 | BD14: X | BE14: X | BF14: X | BG14: X | BH14: X | BK14: X | BL14: X | BM14: X | BN14: X | BO14: X | BR14: X | BS14: X | BT14: X | BU14: X | BV14: X | BY14: X | BZ14: F | CM14: =COUNTIF(R14:CL14,"X") -> 16
B15: Workflow | C15: Funsho | D15: Y | E15: Wed 17 Dec 2025 (1 day delay) | F15: 46010 | G15: N/A | H15: 46031 | I15: =H15+7 -> 46038 | J15: =I15 -> 46038 | K15: VER10-9028 | L15: 35 | M15: 35 | N15: 5 | O15: Team 3 | P15: =SUM(M15:N15) / Capacity!$B$2 -> 5.7142857 | Q15: =SUM(M15:N15)/Capacity!$B$3 -> 5 | U15: X | V15: X | W15: X | X15: X | Y15: X | AB15: F | CM15: =COUNTIF(R15:CL15,"X") -> 5
B16: Tasks | C16: Funsho | E16: Wed 17 Dec 2025 (1 day delay) | F16: 46010 | G16: N/A | H16: 46031 | I16: =H16+7 -> 46038 | J16: =I16 -> 46038 | K16: VER10-9027 | L16: 40 | M16: 0 | O16: N/A | P16: =SUM(M16:N16) / Capacity!$B$2 -> 0 | Q16: =SUM(M16:N16)/Capacity!$B$3 -> 0 | CM16: =COUNTIF(R16:CL16,"X") -> 0
B17: Portfolio/Programme Risk | C17: Funsho | E17: Fri 12 Dec 2025 (Done on time) | F17: 46008 | G17: 46044 | H17: N/A | I17: =G17+7 -> 46051 | J17: =I17 -> 46051 | K17: VER10-9494 | L17: 80 | M17: 60 | N17: 5 | O17: Team 3 | P17: =SUM(M17:N17) / Capacity!$B$2 -> 9.2857143 | Q17: =SUM(M17:N17)/Capacity!$B$3 -> 8.125 | BD17: X | BE17: X | BF17: X | BG17: X | BH17: X | BK17: X | BL17: X | BM17: X | BN17: F | CM17: =COUNTIF(R17:CL17,"X") -> 8
P18: =SUM(M18:N18) / Capacity!$B$2 -> 0 | Q18: =SUM(M18:N18)/Capacity!$B$3 -> 0 | CM18: =COUNTIF(R18:CL18,"X") -> 0
B19: Calculators/Cost Models (Chapter 10) | C19: Minas | E19: Thu 18 Dec 2025 (Done on time) | F19: 46015 | G19: N/A | H19: 46031 | I19: =H19+7 -> 46038 | J19: =I19 -> 46038 | K19: No Epic | L19: 20 | M19: 20 | N19: 6 | O19: Team 5 | P19: =SUM(M19:N19) / Capacity!$B$2 -> 3.7142857 | Q19: =SUM(M19:N19)/Capacity!$B$3 -> 3.25 | U19: X | V19: X | W19: X | CM19: =COUNTIF(R19:CL19,"X") -> 3
B20: Scenario Analysis (Chapter 7) | C20: Venkatesh? (TBC) | E20: Fri, 13 Feb 2026 | F20: Fri, 20 Feb 2026 | G20: 46051 | H20: N/A | I20: =G20+7 -> 46058 | J20: =I20 -> 46058 | K20: VER10-8958 | L20: 140 | M20: 100 | N20: 5 | O20: Team 5 | P20: =SUM(M20:N20) / Capacity!$B$2 -> 15 | Q20: =SUM(M20:N20)/Capacity!$B$3 -> 13.125 | AP20: X | AQ20: X | AR20: X | AS20: X | AT20: X | AW20: X | AX20: X | AY20: X | AZ20: X | BA20: X | BE20: X | BF20: X | BG20: X | CM20: =COUNTIF(R20:CL20,"X") -> 13
B21: Star Rates | C21: Minas? (TBC) | E21: 46045 | F21: 46052 | G21: N/A | H21: 46059 | I21: =H21+7 -> 46066 | J21: =I21 -> 46066 | K21: No Epic | L21: 90 | M21: 60 | O21: Team 2 | P21: =SUM(M21:N21) / Capacity!$B$2 -> 8.5714286 | Q21: =SUM(M21:N21)/Capacity!$B$3 -> 7.5 | AB21: X | AC21: X | AD21: X | AE21: X | AF21: X | AI21: X | AJ21: X | AK21: X | AL21: F | CM21: =COUNTIF(R21:CL21,"X") -> 8
B22: TPE | C22: Venkatesh | E22: 46045 | F22: 46050 | G22: 46059 | H22: N/A | I22: =G22+7 -> 46066 | J22: =I22 -> 46066 | K22: VER10-9184 | L22: 350 | M22: 215 | N22: 4 | O22: Team 4 | P22: =SUM(M22:N22) / Capacity!$B$2 -> 31.285714 | Q22: =SUM(M22:N22)/Capacity!$B$3 -> 27.375 | CM22: =COUNTIF(R22:CL22,"X") -> 0
B23: Dashboards (Power BI) | C23: Minas | E23: Fri, 16 Jan 2026 (Original 24/12/2025) | F23: Wed, 21 Jan 2026 (Original 31/12/2025) | G23: 46051 | H23: N/A | I23: =G23+7 -> 46058 | J23: =I23 -> 46058 | K23: No Epic | L23: 40 | M23: 40 | N23: 2 | O23: Dashboard Team | P23: =SUM(M23:N23) / Capacity!$B$2 -> 6 | Q23: =SUM(M23:N23)/Capacity!$B$3 -> 5.25 | BD23: X | BE23: X | BF23: X | BG23: X | BH23: X | BK23: X | BL23: F | CM23: =COUNTIF(R23:CL23,"X") -> 6
B24: Contractor Fee Library | C24: Minas | E24: 46031 | F24: 46036 | G24: N/A | H24: 46038 | I24: =H24+7 -> 46045 | J24: =I24 -> 46045 | K24: VER10-9271 | L24: 90 | M24: 80 | N24: 3 | O24: Team 2 | P24: =SUM(M24:N24) / Capacity!$B$2 -> 11.857143 | Q24: =SUM(M24:N24)/Capacity!$B$3 -> 10.375 | AL24: X | AM24: X | AP24: X | AQ24: X | AR24: X | AS24: X | AT24: X | AW24: X | AX24: X | AY24: X | AZ24: F | CM24: =COUNTIF(R24:CL24,"X") -> 10
B25: System Access | C25: Minas | E25: 46038 | F25: N/A | G25: N/A | H25: 46038 | I25: =H25+7 -> 46045 | J25: =I25 -> 46045 | K25: No Epic | L25: 40 | M25: 40 | N25: 3 | O25: Team 5 | P25: =SUM(M25:N25) / Capacity!$B$2 -> 6.1428571 | Q25: =SUM(M25:N25)/Capacity!$B$3 -> 5.375 | CM25: =COUNTIF(R25:CL25,"X") -> 0
B26: Audit Log | C26: Minas | E26: 46052 | F26: 46059 | G26: N/A | H26: 46066 | I26: ? | K26: VER10-8955 | L26: 10 | M26: 11 | O26: Team 5 | P26: =SUM(M26:N26) / Capacity!$B$2 -> 1.5714286 | Q26: =SUM(M26:N26)/Capacity!$B$3 -> 1.375 | CM26: =COUNTIF(R26:CL26,"X") -> 0
B27: WBS Tags and Custom Fields | C27: Funsho | E27: Done | F27: Done | G27: Done | H27: Done | I27: Done | J27: Done | K27: VER10-8916, VER10-8268 | L27: Need Estimate | M27: Need Estimate | O27: Team 3 | P27: =SUM(M27:N27) / Capacity!$B$2 -> 0 | Q27: =SUM(M27:N27)/Capacity!$B$3 -> 0 | CM27: =COUNTIF(R27:CL27,"X") -> 0
B28: Reporting Foundation Admin | C28: Funsho | E28: Done | F28: Done | G28: Done | H28: Done | I28: Done | J28: Done | K28: VER10-8476 | L28: 19 | M28: 19 | O28: Team 3 | P28: =SUM(M28:N28) / Capacity!$B$2 -> 2.7142857 | Q28: =SUM(M28:N28)/Capacity!$B$3 -> 2.375 | AB28: X | AC28: X | AD28: F | CM28: =COUNTIF(R28:CL28,"X") -> 2
B29: Inflation | C29: Funsho | E29: Done | F29: Done | G29: Done | H29: Done | I29: Done | J29: Done | K29: VER10-8903, VER10-8570 | L29: 41 | M29: 41 | O29: Team 2 | P29: =SUM(M29:N29) / Capacity!$B$2 -> 5.8571429 | Q29: =SUM(M29:N29)/Capacity!$B$3 -> 5.125 | AZ29: X | BA29: X | BD29: X | BE29: X | BF29: X | BG29: X | BH29: F | CM29: =COUNTIF(R29:CL29,"X") -> 6
P30: =SUM(M30:N30) / Capacity!$B$2 -> 0 | Q30: =SUM(M30:N30)/Capacity!$B$3 -> 0 | CM30: =COUNTIF(R30:CL30,"X") -> 0
B31: AR and O&M fixed reports | E31: Done | F31: Done | G31: Done | H31: Done | I31: Done | J31: Done | K31: VER10-7878, VER10-7879 | L31: 47 | M31: 47 | O31: Team 3 | P31: =SUM(M31:N31) / Capacity!$B$2 -> 6.7142857 | Q31: =SUM(M31:N31)/Capacity!$B$3 -> 5.875 | AP31: X | AQ31: X | AR31: X | AS31: X | AT31: X | AW31: X | AX31: F | CM31: =COUNTIF(R31:CL31,"X") -> 6
B32: CCESS | E32: Done | F32: Done | G32: Done | H32: Done | I32: Done | J32: Done | K32: VER10-6966 | L32: 5 | M32: 5 | O32: Team 3 | P32: =SUM(M32:N32) / Capacity!$B$2 -> 0.71428571 | Q32: =SUM(M32:N32)/Capacity!$B$3 -> 0.625 | AX32: X | AY32: F | CM32: =COUNTIF(R32:CL32,"X") -> 1
L33: =SUM(L3:L32) -> 2179 | M33: =SUM(M4:M32) -> 1768 | N33: =SUM(M3:N32) -> 2333 | P33: =SUM(P3:P32) -> 333.28571 | Q33: =SUM(Q3:Q32) -> 249.1875 | R33: =COUNTIF(R3:R32, "X") -> 1 | S33: =COUNTIF(S3:S32, "X") -> 0 | T33: =COUNTIF(T3:T32, "X") -> 0 | U33: =COUNTIF(U3:U32, "X") -> 3 | V33: =COUNTIF(V3:V32, "X") -> 3 | W33: =COUNTIF(W3:W32, "X") -> 3 | X33: =COUNTIF(X3:X32, "X") -> 2 | Y33: =COUNTIF(Y3:Y32, "X") -> 3 | ... CL33: =COUNTIF(CL3:CL32, "X") -> 0 | CM33: =SUM(CM4:CM32) -> 186

Sheet Completed Actions
A1: A07 | B1: Confirm Vigo resourcing assumptions remain sufficient | C1: Richard / Jerome | D1: 46027 | E1: 46029 | F1: Done
A3: A08 | B3: Brief John Vigo and book design sessions priority LTA then Comparator | C3: Richard | D3: 46027 | E3: 46029 | F3: Done
A5: A09 | B5: Re-establish full-team priority alignment session including Vigo | C5: Richard | D5: 46027 | E5: 46031 | F5: Done
A7: A10 | B7: Attend NH IFT clarification meeting | C7: Venkatesh | D7: 46027 | E7: 46029.333 | F7: Done
A9: A11 | B9: Post-IFT impact assessment on timeline | C9: Venkatesh / Richard | D9: 46027 | E9: 46030 | F9: Done
A11: A05 | B11: Complete internal UAT execution and issue UAT documentation to Louise | C11: Caroline | D11: 46027 | E11: 46028 | F11: Done
A13: A13 | B13: Resolve remaining External UAT P2 defect (Create Project) and confirm retest pass | C13: David / Jerome | D13: 46028 | E13: 46029 | F13: Done
A15: A18 | B15: Populate Stage Gate tracker with historic milestones and next-week forecast dates | C15: Richard | D15: 46028 | E15: 46029 | F15: Done
A17: A19 | B17: Prepare inputs for SRO pack covering story points | C17: Richard | D17: 46028 | E17: 46029 | F17: Done
A19: A22 | B19: Propose and set up weekly unblocker check-in with NH leadership group | C19: Richard | D19: 46028 | E19: 46031 | F19: Done
A21: A23 | B21: Document and confirm agreed NH scope reduction (no supplier-specific library) aligned to FRS | C21: Richard | D21: 46029 | E21: 46031 | F21: Done
A23: A24 | B23: Review NH clarification meeting recording and confirm scope position to proceed | C23: Minas | D23: 46029 | E23: 46029 | F23: Done
... A33: A27 | B33: Track NH sign-off for Release 1D following UAT handover | C33: Caroline | D33: 46029 | E33: 46048 | F33: Done

Sheet Work Plan V2 (OLD)
E1: Design Due Dates
B2: Workstream | C2: Owner | D2: NH upfront clarifcation needed? | E2: PRD (sent to NH for review) | F2: NH Sign Off | G2: VIGO: UI/UX Design | H2: Internal: UI/UX Design | I2: SA (Technical Solution Design) | J2: All Design Activities Due Date | K2: Dev Start | L2: Dev Finish | M2: SG1 | N2: SG2 | O2: SG3 | P2: SG4 | Q2: SG5 | R2: SG6 | S2: SG7 | T2: SG8 | U2: SG9 | V2: SG10 | W2: SG11 | X2: SG12 | Y2: Epics | Z2: Original Estimate | AA2: Updated Estimate | AB2: Priority | AC2: Allocated Team | AD2: Team Work Days (7 SP pd) | AE2: Team Work Days (8 SP pd) | AF2: 46024 | AG2: =AF2+1 -> 46025 | AH2: =AG2+1 -> 46026 | AI2: =AH2+1 -> 46027 | AJ2: =AI2+1 -> 46028 | AK2: =AJ2+1 -> 46029 | AL2: =AK2+1 -> 46030 | AM2: =AL2+1 -> 46031 | AN2: =AM2+1 -> 46032 | ... DM2: =DL2+1 -> 46109 | DN2: =DL2+1 -> 46109 | DO2: =DN2+1 -> 46110 | DP2: =DO2+1 -> 46111 | DQ2: =DP2+1 -> 46112 | DR2: =DQ2+1 -> 46113 | DS2: =DR2+1 -> 46114 | DT2: Total
B3: Carbon Resource Library | C3: Venkatesh | E3: 46015 | F3: 46029 | G3: =F3+2 -> 46031 | H3: N/A | I3: =G3+7 -> 46038 | J3: =I3 -> 46038 | K3: 46038 | L3: 46048 | M3: √ | O3: √ | Z3: 575 | AA3: 55 | AB3: 1 | AC3: Team 1 | AD3: =AA3/Capacity!$B$2 -> 7.8571429 | AE3: =AA3/Capacity!$B$3 -> 6.875 | AT3: X | AW3: X | AX3: X | AY3: X | AZ3: X | BA3: X | BD3: X | BE3: F | DT3: =COUNTIF(AF3:DS3,"X") -> 7
B4: Carbon Item Library | C4: Venkatesh | E4: 46015 | F4: 46029 | G4: =F4+2 -> 46031 | H4: N/A | I4: =G4+7 -> 46038 | J4: =I4 -> 46038 | K4: 46038 | L4: 46052 | M4: √ | O4: √ | AA4: 85 | AB4: 2 | AC4: Team 4 | AD4: =AA4/Capacity!$B$2 -> 12.142857 | AE4: =AA4/Capacity!$B$3 -> 10.625 | AT4: X | AW4: X | AX4: X | AY4: X | AZ4: X | BA4: X | BD4: X | BE4: X | BF4: X | BG4: X | BH4: X | BK4: UnLk | DT4: =COUNTIF(AF4:DS4,"X") -> 11
