Workbook

Sheet Work Plan
E1: Design Due Dates
B2: Workstream | C2: Owner | D2: NH upfront clarifcation needed? | E2: PRD (sent to NH for review) | F2: NH Sign Off | G2: VIGO: UI/UX Design | H2: Internal: UI/UX Design | I2: SA (Technical Solution Design) | J2: All Design Activities Due Date | K2: Epics | L2: Original Estimate | M2: Updated Estimate | N2: Priority | O2: Allocated Team | P2: Team Days (current 25SP/d) | Q2: Team Days (Uplifted 30SP/d) | R2: 46024 | S2: =R2+1 -> 46025 | T2: =S2+1 -> 46026 | U2: =T2+1 -> 46027 | V2: =U2+1 -> 46028 | W2: =V2+1 -> 46029 | X2: =W2+1 -> 46030 | Y2: =X2+1 -> 46031 | Z2: =Y2+1 -> 46032 | ... CL2: =CK2+1 -> 46096 | CM2: Total
B3: Estimate Build – Carbon (incl. EPD) | C3: Venkatesh& Minas | E3: 46015 | J3: =I3 | K3: VER10-8954, VER10-9428, VER10-9464, VER10-9527, VER10-9523 | L3: 575 | M3: =SUM(M4:M11) -> 495 | O3: 2 x Teams | P3: =SUM(M3:N3) / Capacity!$B$2 -> 70.714286 | Q3: =SUM(M3:N3)/(Capacity!$B$3*2) -> 30.9375 | CM3: =SUM(R3:BI3) -> 0
B4: Carbon Resource Library | C4: Venkatesh | E4: 46015 | F4: 46031 | M4: 55 | N4: 1 | O4: Team 1 | P4: =SUM(M4:N4) / Capacity!$B$2 -> 8 | Q4: =SUM(M4:N4)/Capacity!$B$3 -> 7 | Y4: X | AB4: X | AC4: X | AD4: X | AE4: X | AF4: X | AI4: X | AJ4: F | CM4: =COUNTIF(R4:CL4,"X") -> 7
B5: Carbon Item Library | C5: Venkatesh | E5: 46015 | F5: 46031 | M5: 85 | N5: 2 | O5: Team 4 | P5: =SUM(M5:N5) / Capacity!$B$2 -> 12.428571 | Q5: =SUM(M5:N5)/Capacity!$B$3 -> 10.875 | Y5: X | AB5: X | AC5: X | AD5: X | AE5: X | AF5: X | AI5: X | AJ5: X | AK5: X | AL5: X | AM5: X | AP5: UnLk | CM5: =COUNTIF(R5:CL5,"X") -> 11
B6: WBS Carbon & Calc | C6: Venkatesh | E6: 46015 | F6: 46031 | M6: 75 | N6: 4 | O6: Team 4 | P6: =SUM(M6:N6) / Capacity!$B$2 -> 11.285714 | Q6: =SUM(M6:N6)/Capacity!$B$3 -> 9.875 | AP6: X | AQ6: X | AR6: X | AS6: X | AT6: X | AW6: X | AX6: X | AY6: X | AZ6: X | BA6: X | BD6: UnLk | CM6: =COUNTIF(R6:CL6,"X") -> 10
B7: Baseline Assumption | C7: Venkatesh | E7: 46015 | F7: 46031 | M7: 40 | N7: 3 | O7: Team 1 | P7: =SUM(M7:N7) / Capacity!$B$2 -> 6.1428571 | Q7: =SUM(M7:N7)/Capacity!$B$3 -> 5.375 | AK7: X | AL7: X | AM7: X | AP7: X | AQ7: X | AR7: F | CM7: =COUNTIF(R7:CL7,"X") -> 5
B8: EPD | C8: Venkatesh | E8: 46015 | F8: 46031 | M8: 75 | N8: 5 | O8: Team 1 | P8: =SUM(M8:N8) / Capacity!$B$2 -> 11.428571 | Q8: =SUM(M8:N8)/Capacity!$B$3 -> 10 | AS8: X | AT8: X | AW8: X | AX8: X | AY8: X | AZ8: X | BA8: X | BD8: X | BE8: X | BF8: X | BG8: F | CM8: =COUNTIF(R8:CL8,"X") -> 10
B9: Cost to Carbon Library | C9: Venkatesh | E9: 46015 | F9: 46031 | M9: 85 | N9: 7 | O9: Team 1 | P9: =SUM(M9:N9) / Capacity!$B$2 -> 13.142857 | Q9: =SUM(M9:N9)/Capacity!$B$3 -> 11.5 | BH9: X | BK9: X | BL9: X | BM9: X | BN9: X | BO9: X | BR9: X | BS9: X | BT9: X | BU9: X | BV9: X | BY9: X | BZ9: F | CM9: =COUNTIF(R9:CL9,"X") -> 12
B10: Auto-Allocate | C10: Venkatesh | E10: 46015 | F10: 46031 | M10: 40 | N10: 6 | O10: Team 4 | P10: =SUM(M10:N10) / Capacity!$B$2 -> 6.5714286 | Q10: =SUM(M10:N10)/Capacity!$B$3 -> 5.75 | BE10: X | BF10: X | BG10: X | BH10: X | BK10: X | BL10: X | BM10: F | CM10: =COUNTIF(R10:CL10,"X") -> 6
B11: Carbon Reports | C11: MInas | E11: ? | F11: 46031 | M11: 40 | O11: Team 3 | P11: =SUM(M11:N11) / Capacity!$B$2 -> 5.7142857 | Q11: =SUM(M11:N11)/Capacity!$B$3 -> 5 | BR11: X | BS11: X | BT11: X | BU11: X | BV11: X | BY11: F | CM11: =COUNTIF(R11:CL11,"X") -> 5
B12: Interim Forecasting Tool (incl EPD) | C12: Venkatesh | E12: 46031 | F12: 46035 | G12: 46043 | H12: N/A | I12: =G12+7 -> 46050 | J12: =I12 -> 46050 | K12: VER10-8678, VER10-8680, VER10-8682, VER10-8858,, VER10-8679, VER10-8921, VER10-9049,, VER10-9128, | L12: 177 | M12: 200 | N12: 1 | O12: Team 4 | P12: =SUM(M12:N12) / Capacity!$B$2 -> 28.714286 | Q12: =SUM(M12:N12)/Capacity!$B$3 -> 25.125 | R12: X | U12: X | V12: X | W12: X | X12: X | BE12: X | BF12: X | BG12: X | BH12: X | BI12: X | BK12: X | BL12: X | BM12: X | BN12: X | BO12: X | BR12: X | BS12: X | BT12: X | BU12: X | BV12: X | BY12: X | BZ12: X | CA12: X | CB12: X | CC12: F | CM12: =COUNTIF(R12:CL12,"X") -> 24
B13: Long-Term Appraisal | C13: Funsho | E13: Fri 12 Dec 2025 (Done on time) | F13: 46008 | G13: 46037 | H13: N/A | I13: =G13+7 -> 46044 | J13: =I13 -> 46044 | K13: VER10-8565 | L13: 260 | M13: 180 | N13: 4 | O13: Team 2 | P13: =SUM(M13:N13) / Capacity!$B$2 -> 26.285714 | Q13: =SUM(M13:N13)/(Capacity!$B$3*2) -> 11.5 | BH13: X | BK13: X | BL13: X | BM13: X | BN13: X | BO13: X | BR13: X | BS13: X | BT13: X | BU13: X | BV13: X | BY13: X | BZ13: F | CM13: =COUNTIF(R13:CL13,"X") -> 12
B14: Comparator | C14: Funsho | D14: Y | E14: 19/12/2025 (Done on time) | F14: 46015 | G14: 46037 | H14: N/A | I14: =G14+7 -> 46044 | J14: =I14 -> 46044 | K14: VER10-8953 | L14: 120 | M14: 120 | N14: 4 | O14: Team 5 | P14: =SUM(M14:N14) / Capacity!$B$2 -> 17.714286 | Q14: =SUM(M14:N14)/Capacity!$B$3 -> 15.5 | BD14: X | BE14: X | BF14: X | BG14: X | BH14: X | BK14: X | BL14: X | BM14: X | BN14: X | BO14: X | BR14: X | BS14: X | BT14: X | BU14: X | BV14: X | BY14: X | BZ14: F | CM14: =COUNTIF(R14:CL14,"X") -> 16
B15: Workflow | C15: Funsho | D15: Y | E15: Wed 17 Dec 2025 (1 day delay) | F15: 46010 | G15: N/A | H15: 46031 | I15: =H15+7 -> 46038 | J15: =I15 -> 46038 | K15: VER10-9028 | L15: 35 | M15: 35 | N15: 5 | O15: Team 3 | P15: =SUM(M15:N15) / Capacity!$B$2 -> 5.7142857 | Q15: =SUM(M15:N15)/Capacity!$B$3 -> 5 | U15: X | V15: X | W15: X | X15: X | Y15: X | AB15: F | CM15: =COUNTIF(R15:CL15,"X") -> 5
B16: Tasks | C16: Funsho | E16: Wed 17 Dec 2025 (1 day delay) | F16: 46010 | G16: N/A | H16: 46031 | I16: =H16+7 -> 46038 | J16: =I16 -> 46038 | K16: VER10-9027 | L16: 40 | M16: 0 | O16: N/A | P16: =SUM(M16:N16) / Capacity!$B$2 -> 0 | Q16: =SUM(M16:N16)/Capacity!$B$3 -> 0 | CM16: =COUNTIF(R16:CL16,"X") -> 0
B17: Portfolio/Programme Risk | C17: Funsho | E17: Fri 12 Dec 2025 (Done on time) | F17: 46008 | G17: 46044 | H17: N/A | I17: =G17+7 -> 46051 | J17: =I17 -> 46051 | K17: VER10-9494 | L17: 80 | M17: 60 | N17: 5 | O17: Team 3 | P17: =SUM(M17:N17) / Capacity!$B$2 -> 9.2857143 | Q17: =SUM(M17:N17)/Capacity!$B$3 -> 8.125 | BD17: X | BE17: X | BF17: X | BG17: X | BH17: X | BK17: X | BL17: X | BM17: X | BN17: F | CM17: =COUNTIF(R17:CL17,"X") -> 8
P18: =SUM(M18:N18) / Capacity!$B$2 -> 0 | Q18: =SUM(M18:N18)/Capacity!$B$3 -> 0 | CM18: =COUNTIF(R18:CL18,"X") -> 0
B19: Calculators/Cost Models (Chapter 10) | C19: Minas | E19: Thu 18 Dec 2025 (Done on time) | F19: 46015 | G19: N/A | H19: 46031 | I19: =H19+7 -> 46038 | J19: =I19 -> 46038 | K19: No Epic | L19: 20 | M19: 20 | N19: 6 | O19: Team 5 | P19: =SUM(M19:N19) / Capacity!$B$2 -> 3.7142857 | Q19: =SUM(M19:N19)/Capacity!$B$3 -> 3.25 | U19: X | V19: X | W19: X | CM19: =COUNTIF(R19:CL19,"X") -> 3
B20: Scenario Analysis (Chapter 7) | C20: Venkatesh? (TBC) | E20: Fri, 13 Feb 2026 | F20: Fri, 20 Feb 2026 | G20: 46051 | H20: N/A | I20: =G20+7 -> 46058 | J20: =I20 -> 46058 | K20: VER10-8958 | L20: 140 | M20: 100 | N20: 5 | O20: Team 5 | P20: =SUM(M20:N20) / Capacity!$B$2 -> 15 | Q20: =SUM(M20:N20)/Capacity!$B$3 -> 13.125 | AP20: X | AQ20: X | AR20: X | AS20: X | AT20: X | AW20: X | AX20: X | AY20: X | AZ20: X | BA20: X | BE20: X | BF20: X | BG20: X | CM20: =COUNTIF(R20:CL20,"X") -> 13
B21: Star Rates | C21: Minas? (TBC) | E21: 46045 | F21: 46052 | G21: N/A | H21: 46059 | I21: =H21+7 -> 46066 | J21: =I21 -> 46066 | K21: No Epic | L21: 90 | M21: 60 | O21: Team 2 | P21: =SUM(M21:N21) / Capacity!$B$2 -> 8.5714286 | Q21: =SUM(M21:N21)/Capacity!$B$3 -> 7.5 | AB21: X | AC21: X | AD21: X | AE21: X | AF21: X | AI21: X | AJ21: X | AK21: X | AL21: F | CM21: =COUNTIF(R21:CL21,"X") -> 8
B22: TPE | C22: Venkatesh | E22: 46045 | F22: 46050 | G22: 46059 | H22: N/A | I22: =G22+7 -> 46066 | J22: =I22 -> 46066 | K22: VER10-9184 | L22: 350 | M22: 215 | N22: 4 | O22: Team 4 | P22: =SUM(M22:N22) / Capacity!$B$2 -> 31.285714 | Q22: =SUM(M22:N22)/Capacity!$B$3 -> 27.375 | CM22: =COUNTIF(R22:CL22,"X") -> 0
B23: Dashboards (Power BI) | C23: Minas | E23: Fri, 16 Jan 2026 (Original 24/12/2025) | F23: Wed, 21 Jan 2026 (Original 31/12/2025) | G23: 46051 | H23: N/A | I23: =G23+7 -> 46058 | J23: =I23 -> 46058 | K23: No Epic | L23: 40 | M23: 40 | N23: 2 | O23: Dashboard Team | P23: =SUM(M23:N23) / Capacity!$B$2 -> 6 | Q23: =SUM(M23:N23)/Capacity!$B$3 -> 5.25 | BD23: X | BE23: X | BF23: X | BG23: X | BH23: X | BK23: X | BL23: F | CM23: =COUNTIF(R23:CL23,"X") -> 6
B24: Contractor Fee Library | C24: Minas | E24: 46031 | F24: 46036 | G24: N/A | H24: 46038 | I24: =H24+7 -> 46045 | J24: =I24 -> 46045 | K24: VER10-9271 | L24: 90 | M24: 80 | N24: 3 | O24: Team 2 | P24: =SUM(M24:N24) / Capacity!$B$2 -> 11.857143 | Q24: =SUM(M24:N24)/Capacity!$B$3 -> 10.375 | AL24: X | AM24: X | AP24: X | AQ24: X | AR24: X | AS24: X | AT24: X | AW24: X | AX24: X | AY24: X | AZ24: F | CM24: =COUNTIF(R24:CL24,"X") -> 10
B25: System Access | C25: Minas | E25: 46038 | F25: N/A | G25: N/A | H25: 46038 | I25: =H25+7 -> 46045 | J25: =I25 -> 46045 | K25: No Epic | L25: 40 | M25: 40 | N25: 3 | O25: Team 5 | P25: =SUM(M25:N25) / Capacity!$B$2 -> 6.1428571 | Q25: =SUM(M25:N25)/Capacity!$B$3 -> 5.375 | CM25: =COUNTIF(R25:CL25,"X") -> 0
B26: Audit Log | C26: Minas | E26: 46052 | F26: 46059 | G26: N/A | H26: 46066 | I26: ? | K26: VER10-8955 | L26: 10 | M26: 11 | O26: Team 5 | P26: =SUM(M26:N26) / Capacity!$B$2 -> 1.5714286 | Q26: =SUM(M26:N26)/Capacity!$B$3 -> 1.375 | CM26: =COUNTIF(R26:CL26,"X") -> 0
B27: WBS Tags and Custom Fields | C27: Funsho | E27: Done | F27: Done | G27: Done | H27: Done | I27: Done | J27: Done | K27: VER10-8916, VER10-8268 | L27: Need Estimate | M27: Need Estimate | O27: Team 3 | P27: =SUM(M27:N27) / Capacity!$B$2 -> 0 | Q27: =SUM(M27:N27)/Capacity!$B$3 -> 0 | CM27: =COUNTIF(R27:CL27,"X") -> 0
B28: Reporting Foundation Admin | C28: Funsho | E28: Done | F28: Done | G28: Done | H28: Done | I28: Done | J28: Done | K28: VER10-8476 | L28: 19 | M28: 19 | O28: Team 3 | P28: =SUM(M28:N28) / Capacity!$B$2 -> 2.7142857 | Q28: =SUM(M28:N28)/Capacity!$B$3 -> 2.375 | AB28: X | AC28: X | AD28: F | CM28: =COUNTIF(R28:CL28,"X") -> 2
B29: Inflation | C29: Funsho | E29: Done | F29: Done | G29: Done | H29: Done | I29: Done | J29: Done | K29: VER10-8903, VER10-8570 | L29: 41 | M29: 41 | O29: Team 2 | P29: =SUM(M29:N29) / Capacity!$B$2 -> 5.8571429 | Q29: =SUM(M29:N29)/Capacity!$B$3 -> 5.125 | AZ29: X | BA29: X | BD29: X | BE29: X | BF29: X | BG29: X | BH29: F | CM29: =COUNTIF(R29:CL29,"X") -> 6
P30: =SUM(M30:N30) / Capacity!$B$2 -> 0 | Q30: =SUM(M30:N30)/Capacity!$B$3 -> 0 | CM30: =COUNTIF(R30:CL30,"X") -> 0
B31: AR and O&M fixed reports | E31: Done | F31: Done | G31: Done | H31: Done | I31: Done | J31: Done | K31: VER10-7878, VER10-7879 | L31: 47 | M31: 47 | O31: Team 3 | P31: =SUM(M31:N31) / Capacity!$B$2 -> 6.7142857 | Q31: =SUM(M31:N31)/Capacity!$B$3 -> 5.875 | AP31: X | AQ31: X | AR31: X | AS31: X | AT31: X | AW31: X | AX31: F | CM31: =COUNTIF(R31:CL31,"X") -> 6
B32: CCESS | E32: Done | F32: Done | G32: Done | H32: Done | I32: Done | J32: Done | K32: VER10-6966 | L32: 5 | M32: 5 | O32: Team 3 | P32: =SUM(M32:N32) / Capacity!$B$2 -> 0.71428571 | Q32: =SUM(M32:N32)/Capacity!$B$3 -> 0.625 | AX32: X | AY32: F | CM32: =COUNTIF(R32:CL32,"X") -> 1
L33: =SUM(L3:L32) -> 2179 | M33: =SUM(M4:M32) -> 1768 | N33: =SUM(M3:N32) -> 2333 | P33: =SUM(P3:P32) -> 333.28571 | Q33: =SUM(Q3:Q32) -> 249.1875 | R33: =COUNTIF(R3:R32, "X") -> 1 | S33: =COUNTIF(S3:S32, "X") -> 0 | T33: =COUNTIF(T3:T32, "X") -> 0 | U33: =COUNTIF(U3:U32, "X") -> 3 | V33: =COUNTIF(V3:V32, "X") -> 3 | W33: =COUNTIF(W3:W32, "X") -> 3 | X33: =COUNTIF(X3:X32, "X") -> 2 | Y33: =COUNTIF(Y3:Y32, "X") -> 3 | ... CL33: =COUNTIF(CL3:CL32, "X") -> 0 | CM33: =SUM(CM4:CM32) -> 186

Sheet Capacity
C1: per week | D1: whole team
A2: Required per team per day | B2: 7 | C2: =B2*5 -> 35 | D2: =C2*5 -> 175
A3: Ideal per team per day | B3: 8 | C3: =B3*5 -> 40 | D3: =C3*5 -> 200
A5: per dev per day | C5: =C3/28 -> 1.4285714

Sheet Work Plan - Review SP (WIP)
E1: Design Due Dates
B2: Workstream | C2: Owner | D2: NH upfront clarifcation needed? | E2: PRD (sent to NH for review) | F2: NH Sign Off | G2: VIGO: UI/UX Design | H2: Internal: UI/UX Design | I2: SA (Technical Solution Design) | J2: All Design Activities Due Date | K2: Epics | L2: Story Point Estimate for Dev | N2: Assumed Estimate | O2: Team Days (current 25SP/d)
B3: Estimate Build – Carbon | C3: Venkatesh & Funsho | E3: 46015 | F3: 46021 | G3: 46038 | H3: N/A | I3: =G3+7 -> 46045 | J3: =I3 -> 46045 | K3: VER10-8954, VER10-9428, VER10-9464, VER10-9527, VER10-9523 | L3: 575 | M3: 414 | O3: =SUM(L3:N3) / Capacity!$B$2 -> 141.28571
B4: Interim Forecasting Tool | C4: Venkatesh | E4: 46031 | F4: 46035 | G4: 46043 | H4: N/A | I4: =G4+7 -> 46050 | J4: =I4 -> 46050 | K4: VER10-8678, VER10-8680, VER10-8682, VER10-8858,, VER10-8679, VER10-8921, VER10-9049,, VER10-9128, | L4: 177 | M4: 200 | O4: =SUM(L4:N4) / Capacity!$B$2 -> 53.857143
B5: Long-Term Appraisal | C5: Funsho | E5: Fri 12 Dec 2025 (Done on time) | F5: 46008 | G5: 46037 | H5: N/A | I5: =G5+7 -> 46044 | J5: =I5 -> 46044 | K5: VER10-8565 | L5: 260 | M5: 200 | O5: =SUM(L5:N5) / Capacity!$B$2 -> 65.714286
B6: Comparator | C6: Funsho | D6: Y | E6: 19/12/2025 (Done on time) | F6: 46015 | G6: 46037 | H6: N/A | I6: =G6+7 -> 46044 | J6: =I6 -> 46044 | K6: VER10-8953 | L6: 120 | M6: 100 | O6: =SUM(L6:N6) / Capacity!$B$2 -> 31.428571
B7: Workflow | C7: Funsho | D7: Y | E7: Wed 17 Dec 2025 (1 day delay) | F7: 46010 | G7: N/A | H7: 46031 | I7: =H7+7 -> 46038 | J7: =I7 -> 46038 | K7: VER10-9028 | L7: 35 | M7: 35 | O7: =SUM(L7:N7) / Capacity!$B$2 -> 10
B8: Tasks | C8: Funsho | E8: Wed 17 Dec 2025 (1 day delay) | F8: 46010 | G8: N/A | H8: 46031 | I8: =H8+7 -> 46038 | J8: =I8 -> 46038 | K8: VER10-9027 | L8: 40 | M8: 0 | O8: =SUM(L8:N8) / Capacity!$B$2 -> 5.7142857
B9: Portfolio/Programme Risk | C9: Funsho | E9: Fri 12 Dec 2025 (Done on time) | F9: 46008 | G9: 46044 | H9: N/A | I9: =G9+7 -> 46051 | J9: =I9 -> 46051 | K9: VER10-9494 | L9: 80 | M9: 60 | O9: =SUM(L9:N9) / Capacity!$B$2 -> 20
O10: =SUM(L10:N10) / Capacity!$B$2 -> 0
B11: Calculators/Cost Models (Chapter 10) | C11: Minas | E11: Thu 18 Dec 2025 (Done on time) | F11: 46015 | G11: N/A | H11: 46031 | I11: =H11+7 -> 46038 | J11: =I11 -> 46038 | K11: No Epic | L11: 20 | M11: 20 | O11: =SUM(L11:N11) / Capacity!$B$2 -> 5.7142857
B12: Scenario Analysis (Chapter 7) | C12: Venkatesh? (TBC) | E12: Fri, 13 Feb 2026 | F12: Fri, 20 Feb 2026 | G12: 46051 | H12: N/A | I12: =G12+7 -> 46058 | J12: =I12 -> 46058 | K12: VER10-8958 | L12: 140 | M12: 100 | O12: =SUM(L12:N12) / Capacity!$B$2 -> 34.285714
B13: Star Rates | C13: Minas? (TBC) | E13: 46045 | F13: 46052 | G13: N/A | H13: 46059 | I13: =H13+7 -> 46066 | J13: =I13 -> 46066 | K13: No Epic | L13: 90 | M13: 60 | O13: =SUM(L13:N13) / Capacity!$B$2 -> 21.428571
B14: TPE | C14: Venkatesh | E14: 46045 | F14: 46050 | G14: 46059 | H14: N/A | I14: =G14+7 -> 46066 | J14: =I14 -> 46066 | K14: VER10-9184 | L14: 350 | M14: 215 | O14: =SUM(L14:N14) / Capacity!$B$2 -> 80.714286
B15: Dashboards (Power BI) | C15: Minas | E15: 46015 | F15: 46022 | G15: 46051 | H15: N/A | I15: =G15+7 -> 46058 | J15: =I15 -> 46058 | K15: No Epic | L15: 40 | M15: 40 | O15: =SUM(L15:N15) / Capacity!$B$2 -> 11.428571
B16: Contractor Fee Library | C16: Minas | E16: 46031 | F16: 46036 | G16: N/A | H16: 46038 | I16: =H16+7 -> 46045 | J16: =I16 -> 46045 | K16: VER10-9271 | L16: 90 | M16: 80 | O16: =SUM(L16:N16) / Capacity!$B$2 -> 24.285714
B17: System Access | C17: Minas | E17: 46038 | F17: N/A | G17: N/A | H17: 46038 | I17: =H17+7 -> 46045 | J17: =I17 -> 46045 | K17: No Epic | L17: 40 | M17: 40 | O17: =SUM(L17:N17) / Capacity!$B$2 -> 11.428571
B18: Audit Log | C18: Minas | E18: 46052 | F18: 46059 | G18: N/A | H18: 46066 | I18: ? | K18: VER10-8955 | L18: 10 | M18: 11 | O18: =SUM(L18:N18) / Capacity!$B$2 -> 3
B19: WBS Tags and Custom Fields | C19: Funsho | E19: Done | F19: Done | G19: Done | H19: Done | I19: Done | J19: Done | K19: VER10-8916, VER10-8268 | L19: Need Estimate | M19: Need Estimate | O19: =SUM(L19:N19) / Capacity!$B$2 -> 0
B20: Reporting Foundation Admin | C20: Funsho | E20: Done | F20: Done | G20: Done | H20: Done | I20: Done | J20: Done | K20: VER10-8476 | L20: 19 | M20: 19 | O20: =SUM(L20:N20) / Capacity!$B$2 -> 5.4285714
B21: Inflation | C21: Funsho | E21: Done | F21: Done | G21: Done | H21: Done | I21: Done | J21: Done | K21: VER10-8903, VER10-8570 | L21: 41 | M21: 41 | O21: =SUM(L21:N21) / Capacity!$B$2 -> 11.714286
O22: =SUM(L22:N22) / Capacity!$B$2 -> 0
B23: AR and O&M fixed reports | E23: Done | F23: Done | G23: Done | H23: Done | I23: Done | J23: Done | K23: VER10-7878, VER10-7879 | L23: 47 | M23: 47 | O23: =SUM(L23:N23) / Capacity!$B$2 -> 13.428571
B24: CCESS | E24: Done | F24: Done | G24: Done | H24: Done | I24: Done | J24: Done | K24: VER10-6966 | L24: 5 | M24: 5 | O24: =SUM(L24:N24) / Capacity!$B$2 -> 1.4285714
L25: =SUM(L3:L24) -> 2179 | M25: =SUM(M3:M24) -> 1687 | O25: =SUM(O3:O24) -> 552.28571

Sheet Teams Allocation
C1: # points / week | D1: 46013 | E1: 46020 | F1: 45662 | G1: 45669 | H1: 45676 | I1: 45683 | J1: 45690 | K1: 45697 | L1: 45704 | M1: 45711 | N1: 45718 | O1: 45725 | P1: 45732 | Q1: 45739
B2: Team 1 Venkatesh & Sunjeet (3 devs) | C2: 25 | P2: Regression/UAT | Q2: UAT
B3: Team 2 Minas & Manish (3 devs) | C3: 25
B4: Team 3 Minas & Vivek (2 devs) | C4: 20
B5: Team 4 Venkatesh & Amit (4 devs) | C5: 30
B6: Team 5 Minas & Laurence (2 devs) | C6: 25
B8: TOTAL | C8: =SUM(C2:C6) -> 125
B9: To deliver 1500 points (weeks) | C9: =1500/C8 -> 12
B10: To deliver 1500 points in 9 weeks (SP per week) | C10: =1500/9 -> 166.66667
B11: Team | C11: Epic | D11: Reduced Estimate | E11: # weeks | F11: Dependent On | G11: Extra Weeks
B12: Team 1 Venkatesh & Sunjeet | C12: Carbon (incl EPD, Auto Allocate) | D12: =SUM(D13:D20) -> 455 | E12: =D12/$C$2 -> 18.2 | G12: =SUM(E12)-COUNT($D$1:$O$1) -> 6.2
C13: Carbon Resource Library | D13: 55 | E13: =D13/$C$2 -> 2.2
C14: Carbon Item Library | D14: 85 | E14: =D14/$C$2 -> 3.4 | F14: Carbon Resource
C15: WBS Carbon & Calc | D15: 75 | E15: =D15/$C$2 -> 3 | F15: Carbon Libraries
C16: Baseline Assumption | D16: 40 | E16: =D16/$C$2 -> 1.6
C17: EPD | D17: 75 | E17: =D17/$C$2 -> 3
C18: Cost to Carbon Library | D18: 85 | E18: =D18/$C$2 -> 3.4 | F18: Carbon WBS
C19: Auto-Allocate | D19: 40 | E19: =D19/$C$2 -> 1.6 | F19: Carbon Libraries
C20: Carbon Reports | D20: - | E20: -
B22: Team 2 Minas & Manish | C22: Inflation | D22: 41 | E22: =D22/$C$3 -> 1.64 | G22: =SUM(E22:E26)-COUNT($D$1:$O$1) -> 2.44
C23: LTA | D23: 180 | E23: =D23/$C$3 -> 7.2 | F23: Carbon WBS
C24: Star Rates | D24: 60 | E24: =D24/$C$6 -> 2.4
C25: Contractor Fee Library | D25: 80 | E25: =D25/$C$6 -> 3.2 | F25: IFT?
B27: Team 3 Minas & Vivek | C27: Reporting Foundation Admin | D27: 19 | E27: =D27/$C$4 -> 0.95 | G27: =SUM(E27:E33)-COUNT($D$1:$O$1) -> -1.7
C28: Portfolio/Programme Risk | D28: 60 | E28: =D28/$C$4 -> 3
C29: AR and O&M fixed reports | D29: 47 | E29: =D29/$C$4 -> 2.35 | F29: Carbon & Reporting Foundation Admin
C30: CCESS | D30: 5 | E30: =D30/$C$4 -> 0.25 | F30: Carbon & Reporting Foundation Admin
C31: Carbon Reports | D31: 40 | E31: =D31/$C$4 -> 2 | F31: Carbon
C32: Workflow | D32: 35 | E32: =D32/$C$4 -> 1.75
B34: Team 4 Venkatesh & Amit | C34: Supply Chain - Interim Forecasting Tool | D34: 200 | E34: =D34/$C$5 -> 6.6666667 | F34: Carbon WBS | G34: =SUM(E34:E36)-COUNT($D$1:$O$1) -> 1.8333333
C35: TPE | D35: 215 | E35: =D35/$C$5 -> 7.1666667
B37: Team 5 Minas & Laurence | C37: Audit Log | D37: 11 | E37: =D37/$C$6 -> 0.44 | G37: =SUM(E37:E41)-COUNT($D$1:$O$1) -> -0.36
C38: System Access | D38: 40 | E38: =D38/$C$6 -> 1.6
C39: Calculators/Cost Models | D39: 20 | E39: =D39/$C$6 -> 0.8
C40: Comparator | D40: 120 | E40: =D40/$C$3 -> 4.8 | F40: Carbon WBS
C41: Scenario Analysis | D41: 100 | E41: =D41/$C$3 -> 4 | F41: Comparator
B43: Work Streams | D43: Reduced Estimate | E43: Team
B44: Dashboards (Power BI) | D44: 40 | E44: Jonny?
B45: WBS Tags and Custom Fields | D45: Need Estimate | E45: ?

Sheet MVP Meetings
B1: Topic | C1: Owner | D1: Meeting (UK timezone) | E1: Meeting (AU timezone) | F1: Notes
B2: EPD/Cost to Carbon Factor | C2: Venkatesh | D2: Tue 23rd Dec 10PM-11PM | E2: Wed 24th Dec 9AM-10AM | F2: Meeting done
B3: LTA | C3: Minas | D3: Wed 24th Dec 8AM-9:30AM | E3: Wed24th Dec 7PM-8:30PM | F3: Meeting done
B4: TPE & Auto Allocate (Cost & Carbon) | C4: Venkatesh | D4: Sun 28th Dec 10PM-11:30PM | E4: Mon 29th Dec 9AM-10:30AM | F4: Meeting done
B5: Scenario Analysis (Chapter 7) | C5: Minas | D5: Mon 29th Dec 7AM-8:30AM | E5: Mon 29th Dec 6PM-7:30PM
B6: Carbon Reports | C6: Minas
B9: Supply Chain - Interim Forecasting Tool (incl EPD) | C9: Venkatesh | D9: N/A | E9: N/A | F9: Venkatesh needs meeting with NH
B10: Dashboards (Power BI) | C10: Minas
B11: Comparator | C11: Minas
B12: Workflow | C12: Minas
B13: Tasks | C13: Minas
B14: Calculators/Cost Models (Chapter 10) | C14: Minas
B15: Star Rates | C15: Minas
B16: Contractor Fee Library | C16: Minas
D18: UK | E18: AU | F18: Status | G18: Topic
B19: Mark's avail. | D19: Wed 24th Dec UK morning | E19: Wed 24th AU evening | F19: Taken | G19: LTA
D20: Sat 27th Dec 7AM-9AM | E20: Sat 27th Dec 6PM-8PM | F20: X
D21: Sun 28th Dec 7AM-9AM | E21: Sun 28th Dec 6PM-8PM | F21: X
D22: Sun 28th Dec 10PM-11:30PM | E22: Mon 29th Dec 9AM-10:30AM | F22: Taken | G22: TPE & Auto Allocate (Cost & Carbon)
D23: Mon 29th Dec 7AM-9AM | E23: Mon 29th Dec 6PM-8PM | F23: Taken | G23: Scenario Analysis (Chapter 7)
D24: Mon 29th Dec 10PM-11:30PM | E24: Tue 30th Dec 9AM-10:30AM | F24: After MVP deadline (Mon 29th)
D25: Fri 2nd Jan UK morning | E25: Fri 2nd Jan AU evening | F25: After MVP deadline (Mon 29th)

Sheet Work Plan V2
E1: Design Due Dates
B2: Workstream | C2: Owner | D2: NH upfront clarifcation needed? | E2: PRD (sent to NH for review) | F2: NH Sign Off | G2: VIGO: UI/UX Design | H2: Internal: UI/UX Design | I2: SA (Technical Solution Design) | J2: All Design Activities Due Date | K2: Dev Start | L2: Dev Finish | M2: SG1 | N2: SG2 | O2: SG3 | P2: SG4 | Q2: SG5 | R2: SG6 | S2: SG7 | T2: SG8 | U2: SG9 | V2: SG10 | W2: Epics | X2: Original Estimate | Y2: Updated Estimate | Z2: Priority | AA2: Allocated Team | AB2: Team Work Days (7 SP pd) | AC2: Team Work Days (8 SP pd) | AD2: 46024 | AE2: =AD2+1 -> 46025 | AF2: =AE2+1 -> 46026 | AG2: =AF2+1 -> 46027 | AH2: =AG2+1 -> 46028 | AI2: =AH2+1 -> 46029 | AJ2: =AI2+1 -> 46030 | AK2: =AJ2+1 -> 46031 | AL2: =AK2+1 -> 46032 | ... CW2: =CV2+1 -> 46095 | CX2: =CV2+1 -> 46095 | CY2: =CX2+1 -> 46096 | CZ2: =CY2+1 -> 46097 | DA2: =CZ2+1 -> 46098 | DB2: =DA2+1 -> 46099 | DC2: =DB2+1 -> 46100 | DD2: =DC2+1 -> 46101 | DE2: =DC2+1 -> 46101 | DF2: =DE2+1 -> 46102 | DG2: =DF2+1 -> 46103 | DH2: =DG2+1 -> 46104 | DI2: =DH2+1 -> 46105 | DJ2: =DI2+1 -> 46106 | DK2: =DJ2+1 -> 46107 | DL2: =DJ2+1 -> 46107 | DM2: =DL2+1 -> 46108 | DN2: =DM2+1 -> 46109 | DO2: =DN2+1 -> 46110 | DP2: =DO2+1 -> 46111 | DQ2: =DP2+1 -> 46112 | DR2: Total
B3: Carbon Resource Library | C3: Venkatesh | E3: 46015 | F3: 46029 | G3: =F3+2 -> 46031 | H3: N/A | I3: =G3+7 -> 46038 | J3: =I3 -> 46038 | M3: √ | O3: √ | X3: 575 | Y3: 55 | Z3: 1 | AA3: Team 1 | AB3: =Y3/Capacity!$B$2 -> 7.8571429 | AC3: =Y3/Capacity!$B$3 -> 6.875 | AR3: X | AU3: X | AV3: X | AW3: X | AX3: X | AY3: X | BB3: X | BC3: F | DR3: =COUNTIF(AD3:DQ3,"X") -> 7
B4: Carbon Item Library | C4: Venkatesh | E4: 46015 | F4: 46029 | G4: =F4+2 -> 46031 | H4: N/A | I4: =G4+7 -> 46038 | J4: =I4 -> 46038 | M4: √ | O4: √ | Y4: 85 | Z4: 2 | AA4: Team 4 | AB4: =Y4/Capacity!$B$2 -> 12.142857 | AC4: =Y4/Capacity!$B$3 -> 10.625 | AR4: X | AU4: X | AV4: X | AW4: X | AX4: X | AY4: X | BB4: X | BC4: X | BD4: X | BE4: X | BF4: X | BI4: UnLk | DR4: =COUNTIF(AD4:DQ4,"X") -> 11
B5: WBS Carbon & Calc | C5: Venkatesh | E5: 46015 | F5: 46031 | G5: =F5+7 -> 46038 | H5: N/A | I5: =G5+7 -> 46045 | J5: =I5 -> 46045 | M5: √ | Y5: 75 | Z5: 4 | AA5: Team 4 | AB5: =Y5/Capacity!$B$2 -> 10.714286 | AC5: =Y5/Capacity!$B$3 -> 9.375 | BI5: X | BJ5: X | BK5: X | BL5: X | BM5: X | BP5: X | BQ5: X | BR5: X | BS5: X | BT5: X | BW5: UnLk | DR5: =COUNTIF(AD5:DQ5,"X") -> 10
B6: Baseline Assumption | C6: Venkatesh | E6: 46015 | F6: 46031 | G6: =F6+7 -> 46038 | H6: N/A | I6: =G6+5 -> 46043 | J6: =I6 -> 46043 | M6: √ | Y6: 40 | Z6: 3 | AA6: Team 1 | AB6: =Y6/Capacity!$B$2 -> 5.7142857 | AC6: =Y6/Capacity!$B$3 -> 5 | BC6: X | BD6: X | BE6: X | BF6: X | BI6: X | BJ6: F | DR6: =COUNTIF(AD6:DQ6,"X") -> 5
B7: EPD | C7: Venkatesh | E7: 46015 | F7: 46031 | G7: =F7+14 -> 46045 | H7: N/A | I7: =G7+6 -> 46051 | J7: =I7 -> 46051 | M7: √ | Y7: 75 | Z7: 5 | AA7: Team 1 | AB7: =Y7/Capacity!$B$2 -> 10.714286 | AC7: =Y7/Capacity!$B$3 -> 9.375 | BJ7: X | BK7: X | BL7: X | BM7: X | BP7: X | BQ7: X | BR7: X | BS7: X | BT7: X | BW7: X | BX7: X | BY7: F | DR7: =COUNTIF(AD7:DQ7,"X") -> 11
B8: Cost to Carbon Library | C8: Venkatesh | E8: 46015 | F8: 46038 | G8: =F8+7 -> 46045 | H8: N/A | I8: =G8+7 -> 46052 | J8: =I8 -> 46052 | M8: √ | Y8: 85 | Z8: 7 | AA8: Team 1 | AB8: =Y8/Capacity!$B$2 -> 12.142857 | AC8: =Y8/Capacity!$B$3 -> 10.625 | BY8: X | BZ8: X | CA8: X | CD8: X | CE8: X | CF8: X | CG8: X | CH8: X | CK8: X | CL8: X | CM8: X | CN8: X | CO8: F | DR8: =COUNTIF(AD8:DQ8,"X") -> 12
B9: Auto-Allocate | C9: Venkatesh | E9: 46015 | F9: 46038 | G9: =F9+7 -> 46045 | H9: N/A | I9: =G9+7 -> 46052 | J9: =I9 -> 46052 | M9: √ | Y9: 40 | Z9: 6 | AA9: Team 4 | AB9: =Y9/Capacity!$B$2 -> 5.7142857 | AC9: =Y9/Capacity!$B$3 -> 5 | BW9: X | BX9: X | BY9: X | BZ9: X | CA9: X | CD9: X | CE9: X | CF9: X | CG9: X | CH9: X | CK9: F | DR9: =COUNTIF(AD9:DQ9,"X") -> 10
B10: Carbon Reports | C10: Minas | E10: 46038 | F10: =E10+7 -> 46045 | G10: =F10+7 -> 46052 | H10: N/A | I10: =G10+7 -> 46059 | J10: =I10 -> 46059 | Y10: 40 | AA10: Team 3 | AB10: =Y10/Capacity!$B$2 -> 5.7142857 | AC10: =Y10/Capacity!$B$3 -> 5 | BS10: X | BT10: X | BW10: X | BX10: X | BY10: X | BZ10: F | DR10: =COUNTIF(AD10:DQ10,"X") -> 5
B11: Interim Forecasting Tool (incl EPD) | C11: Venkatesh | E11: 46031 | F11: 46037 | G11: =F11+7 -> 46044 | H11: N/A | I11: =G11+7 -> 46051 | J11: =I11 -> 46051 | W11: VER10-8678, VER10-8680, VER10-8682, VER10-8858,, VER10-8679, VER10-8921, VER10-9049,, VER10-9128, | X11: 177 | Y11: 200 | Z11: 1 | AA11: Team 4 | AB11: =Y11/Capacity!$B$2 -> 28.571429 | AC11: =Y11/Capacity!$B$3 -> 25 | AG11: X | AH11: X | AI11: X | AJ11: X | AK11: X | AN11: X | AO11: X | AP11: X | AQ11: X | CK11: X | CL11: X | CM11: X | CN11: X | CO11: X | CR11: X | CS11: X | CT11: X | CU11: X | CV11: X | CY11: X | CZ11: X | DA11: X | DB11: X | DC11: X | DF11: X | DG11: X | DH11: F | DR11: =COUNTIF(AD11:DQ11,"X") -> 26
B12: Long-Term Appraisal | C12: Minas | E12: Fri 12 Dec 2025 | F12: 46045 | G12: =F12+7 -> 46052 | H12: N/A | I12: =G12+7 -> 46059 | J12: =I12 -> 46059 | M12: √ | W12: VER10-9697, VER10-9698, VER10-9699, VER10-9700, VER10-9701, VER10-9702 | X12: 260 | Y12: 180 | Z12: 4 | AA12: Team 2 | AB12: =Y12/Capacity!$B$2 -> 25.714286 | AC12: =Y12/Capacity!$B$3 -> 22.5 | BE12: X | BF12: X | BI12: X | BJ12: X | BK12: X | BL12: X | BM12: X | BP12: X | BQ12: X | BR12: X | BS12: X | BT12: X | BW12: X | BX12: X | BY12: X | BZ12: X | CA12: X | CD12: X | CE12: X | CF12: X | CG12: X | CH12: X | CK12: X | CL12: X | CM12: X | CN12: X | CO12: F | DR12: =COUNTIF(AD12:DQ12,"X") -> 26
B13: Comparator | C13: Minas | D13: Y | E13: Fri 12 Dec 2025 | F13: 46041 | G13: =F13+7 -> 46048 | H13: N/A | I13: =G13+7 -> 46055 | J13: =I13 -> 46055 | M13: √ | W13: VER10-8953 | X13: 120 | Y13: 120 | Z13: 4 | AA13: Team 5 | AB13: =Y13/Capacity!$B$2 -> 17.142857 | AC13: =Y13/Capacity!$B$3 -> 15 | BI13: X | BJ13: X | BK13: X | BL13: X | BM13: X | BP13: X | BQ13: X | BR13: X | BS13: X | BT13: X | BW13: X | BX13: X | BY13: X | BZ13: X | CA13: X | CD13: F | DR13: =COUNTIF(AD13:DQ13,"X") -> 15
B14: Workflow | C14: Minas | D14: Y | E14: Wed 17 Dec 2025 | F14: 46031 | G14: N/A | H14: 46038 | I14: =H14+7 -> 46045 | J14: =I14 -> 46045 | M14: √ | W14: VER10-9028 | X14: 35 | Y14: 35 | Z14: 5 | AA14: Team 3 | AB14: =Y14/Capacity!$B$2 -> 5 | AC14: =Y14/Capacity!$B$3 -> 4.375 | AV14: X | AW14: X | AX14: X | AY14: X | BB14: X | BC14: F | DR14: =COUNTIF(AD14:DQ14,"X") -> 5
B15: Portfolio/Programme Risk | C15: Minas | E15: Fri 12 Dec 2025 | F15: 46041 | G15: =F15+7 -> 46048 | H15: N/A | I15: =G15+7 -> 46055 | J15: =I15 -> 46055 | M15: √ | W15: VER10-9494 | X15: 80 | Y15: 60 | Z15: 5 | AA15: Team 3 | AB15: =Y15/Capacity!$B$2 -> 8.5714286 | AC15: =Y15/Capacity!$B$3 -> 7.5 | BI15: X | BJ15: X | BK15: X | BL15: X | BM15: X | BP15: X | BQ15: X | BR15: X | BS15: F | DR15: =COUNTIF(AD15:DQ15,"X") -> 8
B16: Calculators/Cost Models (Chapter 10) | C16: Minas | E16: Thu 18 Dec 2025 | F16: 46031 | G16: N/A | H16: 46038 | I16: =H16+7 -> 46045 | J16: =I16 -> 46045 | M16: √ | W16: No Epic | X16: 20 | Y16: 20 | Z16: 6 | AA16: Team 5 | AB16: =Y16/Capacity!$B$2 -> 2.8571429 | AC16: =Y16/Capacity!$B$3 -> 2.5 | BB16: X | BC16: X | BD16: X | BE16: F | DR16: =COUNTIF(AD16:DQ16,"X") -> 3
B17: Scenario Analysis (Chapter 7) | C17: Minas? (TBC) | E17: 46045 | F17: =E17+7 -> 46052 | G17: =F17+7 -> 46059 | H17: N/A | I17: =G17+7 -> 46066 | J17: =I17 -> 46066 | W17: VER10-8958 | X17: 140 | Y17: 100 | Z17: 5 | AA17: Team 3 | AB17: =Y17/Capacity!$B$2 -> 14.285714 | AC17: =Y17/Capacity!$B$3 -> 12.5 | CD17: X | CE17: X | CF17: X | CG17: X | CH17: X | CK17: X | CL17: X | CM17: X | CN17: X | CO17: X | CS17: X | CT17: X | CU17: X | CV17: F | DR17: =COUNTIF(AD17:DQ17,"X") -> 13
B18: Star Rates | C18: Minas? (TBC) | E18: 46059 | F18: 46064 | G18: N/A | H18: 46066 | I18: =H18+7 -> 46073 | J18: =I18 -> 46073 | W18: No Epic | X18: 90 | Y18: 60 | AA18: Team 2 | AB18: =Y18/Capacity!$B$2 -> 8.5714286 | AC18: =Y18/Capacity!$B$3 -> 7.5 | AU18: X | AV18: X | AW18: X | AX18: X | AY18: X | BB18: X | BC18: X | BD18: X | BE18: F | DR18: =COUNTIF(AD18:DQ18,"X") -> 8
B19: TPE | C19: Venkatesh | E19: 46052 | F19: =E19+7 -> 46059 | G19: =F19+7 -> 46066 | H19: N/A | I19: =G19+7 -> 46073 | J19: =I19 -> 46073 | W19: VER10-9184 | X19: 350 | Y19: 215 | Z19: 4 | AA19: Team 5 | AB19: =Y19/Capacity!$B$2 -> 30.714286 | AC19: =Y19/Capacity!$B$3 -> 26.875 | CD19: X | CE19: X | CF19: X | CG19: X | CH19: X | CK19: X | CL19: X | CM19: X | CN19: X | CO19: X | CR19: X | CS19: X | CT19: X | CU19: X | CV19: X | CY19: X | CZ19: X | DA19: X | DB19: X | DC19: X | DF19: X | DG19: F | DR19: =COUNTIF(AD19:DQ19,"X") -> 21
B20: Dashboards (Power BI) | C20: Minas | E20: 46031 | F20: =E20+7 -> 46038 | G20: N/A | H20: N/A | I20: N/A | J20: N/A | W20: No Epic | X20: 40 | Y20: 40 | Z20: 2 | AA20: Dashboard Team | AB20: =Y20/Capacity!$B$2 -> 5.7142857 | AC20: =Y20/Capacity!$B$3 -> 5 | AU20: X | AV20: X | AW20: X | AX20: X | AY20: X | BB20: F | DR20: =COUNTIF(AD20:DQ20,"X") -> 5
B21: Contractor Fee Library | C21: Minas | E21: 46052 | F21: 46057 | G21: N/A | H21: =F21+7 -> 46064 | I21: =H21+7 -> 46071 | J21: =I21 -> 46071 | W21: VER10-9271 | X21: 90 | Y21: 80 | Z21: 3 | AA21: Team 2 | AB21: =Y21/Capacity!$B$2 -> 11.428571 | AC21: =Y21/Capacity!$B$3 -> 10 | CO21: X | CR21: X | CS21: X | CT21: X | CU21: X | CV21: X | CY21: X | CZ21: X | DA21: X | DB21: X | DC21: F | DR21: =COUNTIF(AD21:DQ21,"X") -> 10
B22: System Access | C22: Minas | E22: 46059 | F22: N/A | G22: N/A | H22: =E22+7 -> 46066 | I22: =H22+7 -> 46073 | J22: =I22 -> 46073 | W22: VER10-8452 | X22: 40 | Y22: 40 | Z22: 3 | AA22: Team 5 | AB22: =Y22/Capacity!$B$2 -> 5.7142857 | AC22: =Y22/Capacity!$B$3 -> 5 | AG22: X | AH22: X | AI22: X | AJ22: X | AK22: X | AN22: X | AO22: X | AP22: X | AQ22: X | AR22: X | AU22: F | DR22: =COUNTIF(AD22:DQ22,"X") -> 10
B23: Audit Log | C23: Minas | E23: 46031 | F23: =E23+7 -> 46038 | G23: N/A | H23: =F23+7 -> 46045 | I23: 46045 | J23: =I23 -> 46045 | W23: VER10-8955, VER10-6972 | X23: 10 | Y23: 11 | AA23: Team 5 | AB23: =Y23/Capacity!$B$2 -> 1.5714286 | AC23: =Y23/Capacity!$B$3 -> 1.375 | AX23: X | AY23: F | DR23: =COUNTIF(AD23:DQ23,"X") -> 1
B24: WBS Tags and Custom Fields | C24: Minas | E24: Done | F24: Done | G24: Done | H24: Done | I24: Done | J24: Done | M24: √ | N24: √ | O24: √ | P24: √ | Q24: √ | R24: √ | W24: VER10-8916, VER10-8268 | X24: 10 | Y24: 10 | AA24: Team 2 | AB24: =Y24/Capacity!$B$2 -> 1.4285714 | AC24: =Y24/Capacity!$B$3 -> 1.25 | AJ24: X | AK24: F | DR24: =COUNTIF(AD24:DQ24,"X") -> 1
B25: Reporting Foundation Admin | C25: Minas | E25: Done | F25: Done | G25: Done | H25: Done | I25: Done | J25: Done | M25: √ | N25: √ | O25: √ | P25: √ | Q25: √ | R25: √ | W25: VER10-8476 | X25: 19 | Y25: 19 | AA25: Team 3 | AB25: =Y25/Capacity!$B$2 -> 2.7142857 | AC25: =Y25/Capacity!$B$3 -> 2.375 | AH25: X | AI25: X | AJ25: X | AK25: F | DR25: =COUNTIF(AD25:DQ25,"X") -> 3
B26: Inflation | C26: Minas | E26: Done | F26: Done | G26: Done | H26: Done | I26: Done | J26: Done | M26: √ | N26: √ | O26: √ | P26: √ | Q26: √ | R26: √ | W26: VER10-8903, VER10-8570 | X26: 41 | Y26: 41 | AA26: Team 2 | AB26: =Y26/Capacity!$B$2 -> 5.8571429 | AC26: =Y26/Capacity!$B$3 -> 5.125 | AN26: X | AO26: X | AP26: X | AQ26: X | AR26: X | AU26: F | DR26: =COUNTIF(AD26:DQ26,"X") -> 5
B27: AR and O&M fixed reports | C27: Minas | E27: Done | F27: Done | G27: Done | H27: Done | I27: Done | J27: Done | M27: √ | N27: √ | O27: √ | P27: √ | Q27: √ | R27: √ | W27: VER10-7878, VER10-7879 | X27: 47 | Y27: 47 | AA27: Team 3 | AB27: =Y27/Capacity!$B$2 -> 6.7142857 | AC27: =Y27/Capacity!$B$3 -> 5.875 | AK27: X | AN27: X | AO27: X | AP27: X | AQ27: X | AR27: X | AU27: F | DR27: =COUNTIF(AD27:DQ27,"X") -> 6
B28: CCESS | C28: Minas | E28: Done | F28: Done | G28: Done | H28: Done | I28: Done | J28: Done | M28: √ | N28: √ | O28: √ | P28: √ | W28: VER10-6966 | X28: 5 | Y28: 5 | AA28: Team 3 | AB28: =Y28/Capacity!$B$2 -> 0.71428571 | AC28: =Y28/Capacity!$B$3 -> 0.625 | BZ28: X | CA28: F | DR28: =COUNTIF(AD28:DQ28,"X") -> 1
X29: =SUM(X3:X28) -> 2149 | Y29: =SUM(Y3:Y28) -> 1778 | Z29: =SUM(Y3:Z28) -> 1848 | AB29: =SUM(AB3:AB28) -> 254 | AC29: =SUM(AC3:AC28) -> 222.25 | AD29: =COUNTIF(AD3:AD28, "X") -> 0 | AE29: =COUNTIF(AE3:AE28, "X") -> 0 | AF29: =COUNTIF(AF3:AF28, "X") -> 0 | AG29: =COUNTIF(AG3:AG28, "X") -> 2 | AH29: =COUNTIF(AH3:AH28, "X") -> 3 | AI29: =COUNTIF(AI3:AI28, "X") -> 3 | AJ29: =COUNTIF(AJ3:AJ28, "X") -> 4 | AK29: =COUNTIF(AK3:AK28, "X") -> 3 | ... DQ29: =COUNTIF(DQ3:DQ28, "X") -> 0 | DR29: =SUM(DR3:DR28) -> 238
B31: Key | C31: In progress | AA31: Team 1 | AD31: =COUNTIFS($AA$3:$AA$28, $AA31, AD$3:AD$28,"X") -> 0 | AE31: =COUNTIFS($AA$3:$AA$28, $AA31, AE$3:AE$28,"X") -> 0 | AF31: =COUNTIFS($AA$3:$AA$28, $AA31, AF$3:AF$28,"X") -> 0 | AG31: =COUNTIFS($AA$3:$AA$28, $AA31, AG$3:AG$28,"X") -> 0 | AH31: =COUNTIFS($AA$3:$AA$28, $AA31, AH$3:AH$28,"X") -> 0 | AI31: =COUNTIFS($AA$3:$AA$28, $AA31, AI$3:AI$28,"X") -> 0 | AJ31: =COUNTIFS($AA$3:$AA$28, $AA31, AJ$3:AJ$28,"X") -> 0 | AK31: =COUNTIFS($AA$3:$AA$28, $AA31, AK$3:AK$28,"X") -> 0 | ... DQ31: =COUNTIFS($AA$3:$AA$28, $AA31, DQ$3:DQ$28,"X") -> 0 | DR31: =SUMIFS($DR$3:$DR$28, $AA$3:$AA$28, AA31) -> 28
C32: Complete | AA32: Team 2 | AD32: =COUNTIFS($AA$3:$AA$28, $AA32, AD$3:AD$28,"X") -> 0 | AE32: =COUNTIFS($AA$3:$AA$28, $AA32, AE$3:AE$28,"X") -> 0 | AF32: =COUNTIFS($AA$3:$AA$28, $AA32, AF$3:AF$28,"X") -> 0 | AG32: =COUNTIFS($AA$3:$AA$28, $AA32, AG$3:AG$28,"X") -> 0 | AH32: =COUNTIFS($AA$3:$AA$28, $AA32, AH$3:AH$28,"X") -> 0 | AI32: =COUNTIFS($AA$3:$AA$28, $AA32, AI$3:AI$28,"X") -> 0 | AJ32: =COUNTIFS($AA$3:$AA$28, $AA32, AJ$3:AJ$28,"X") -> 1 | AK32: =COUNTIFS($AA$3:$AA$28, $AA32, AK$3:AK$28,"X") -> 0 | ... DQ32: =COUNTIFS($AA$3:$AA$28, $AA32, DQ$3:DQ$28,"X") -> 0 | DR32: =SUMIFS($DR$3:$DR$28, $AA$3:$AA$28, AA32) -> 50
C33: At risk (Mitigation) | AA33: Team 3 | AD33: =COUNTIFS($AA$3:$AA$28, $AA33, AD$3:AD$28,"X") -> 0 | AE33: =COUNTIFS($AA$3:$AA$28, $AA33, AE$3:AE$28,"X") -> 0 | AF33: =COUNTIFS($AA$3:$AA$28, $AA33, AF$3:AF$28,"X") -> 0 | AG33: =COUNTIFS($AA$3:$AA$28, $AA33, AG$3:AG$28,"X") -> 0 | AH33: =COUNTIFS($AA$3:$AA$28, $AA33, AH$3:AH$28,"X") -> 1 | AI33: =COUNTIFS($AA$3:$AA$28, $AA33, AI$3:AI$28,"X") -> 1 | AJ33: =COUNTIFS($AA$3:$AA$28, $AA33, AJ$3:AJ$28,"X") -> 1 | AK33: =COUNTIFS($AA$3:$AA$28, $AA33, AK$3:AK$28,"X") -> 1 | ... DQ33: =COUNTIFS($AA$3:$AA$28, $AA33, DQ$3:DQ$28,"X") -> 0 | DR33: =SUMIFS($DR$3:$DR$28, $AA$3:$AA$28, AA33) -> 41
C34: Blocked | AA34: Team 4 | AD34: =COUNTIFS($AA$3:$AA$28, $AA34, AD$3:AD$28,"X") -> 0 | AE34: =COUNTIFS($AA$3:$AA$28, $AA34, AE$3:AE$28,"X") -> 0 | AF34: =COUNTIFS($AA$3:$AA$28, $AA34, AF$3:AF$28,"X") -> 0 | AG34: =COUNTIFS($AA$3:$AA$28, $AA34, AG$3:AG$28,"X") -> 1 | AH34: =COUNTIFS($AA$3:$AA$28, $AA34, AH$3:AH$28,"X") -> 1 | AI34: =COUNTIFS($AA$3:$AA$28, $AA34, AI$3:AI$28,"X") -> 1 | AJ34: =COUNTIFS($AA$3:$AA$28, $AA34, AJ$3:AJ$28,"X") -> 1 | AK34: =COUNTIFS($AA$3:$AA$28, $AA34, AK$3:AK$28,"X") -> 1 | ... DQ34: =COUNTIFS($AA$3:$AA$28, $AA34, DQ$3:DQ$28,"X") -> 0 | DR34: =SUMIFS($DR$3:$DR$28, $AA$3:$AA$28, AA34) -> 57
AA35: Team 5 | AD35: =COUNTIFS($AA$3:$AA$28, $AA35, AD$3:AD$28,"X") -> 0 | AE35: =COUNTIFS($AA$3:$AA$28, $AA35, AE$3:AE$28,"X") -> 0 | AF35: =COUNTIFS($AA$3:$AA$28, $AA35, AF$3:AF$28,"X") -> 0 | AG35: =COUNTIFS($AA$3:$AA$28, $AA35, AG$3:AG$28,"X") -> 1 | AH35: =COUNTIFS($AA$3:$AA$28, $AA35, AH$3:AH$28,"X") -> 1 | AI35: =COUNTIFS($AA$3:$AA$28, $AA35, AI$3:AI$28,"X") -> 1 | AJ35: =COUNTIFS($AA$3:$AA$28, $AA35, AJ$3:AJ$28,"X") -> 1 | AK35: =COUNTIFS($AA$3:$AA$28, $AA35, AK$3:AK$28,"X") -> 1 | ... DQ35: =COUNTIFS($AA$3:$AA$28, $AA35, DQ$3:DQ$28,"X") -> 0 | DR35: =SUMIFS($DR$3:$DR$28, $AA$3:$AA$28, AA35) -> 50
AA36: Total | AD36: =SUM(AD31:AD35) -> 0 | AE36: =SUM(AE31:AE35) -> 0 | AF36: =SUM(AF31:AF35) -> 0 | AG36: =SUM(AG31:AG35) -> 2 | AH36: =SUM(AH31:AH35) -> 3 | AI36: =SUM(AI31:AI35) -> 3 | AJ36: =SUM(AJ31:AJ35) -> 4 | AK36: =SUM(AK31:AK35) -> 3 | ... DQ36: =SUM(DQ31:DQ35) -> 0

Sheet Stage Gate Tracker
A1: Gate | B1: Owner | C1: Rationale | D1: Pass Criteria (Evidence Required) | E1: Carbon Resource Library | F1: Carbon Item Library | G1: WBS Carbon & Calc | H1: Baseline Assumption | I1: EPD | J1: Cost to Carbon Library | K1: Auto-Allocate | L1: Carbon Reports | M1: Interim Forecasting Tool (incl EPD) | N1: Long-Term Appraisal | O1: Comparator | P1: Workflow | Q1: Portfolio/Programme Risk | R1: Calculators/Cost Models (Chapter 10) | S1: Scenario Analysis (Chapter 7) | T1: Star Rates | U1: TPE | V1: Dashboards (Power BI) | W1: Contractor Fee Library | X1: System Access | Y1: Audit Log | Z1: WBS Tags and Custom Fields | AA1: Reporting Foundation Admin | AB1: Inflation | AC1: AR and O&M fixed reports | AD1: CCESS
A2: 1. Individual PRDs Drafted | B2: Minas | C2: Ensures scope and requirements are explicit before design and build begin, avoiding downstream rework and ambiguity. | D2: • PRDs drafted for each of the MVP epics | E2: 46015 | F2: 46015 | G2: 46015 | H2: 46015 | I2: 46015 | J2: 46015 | K2: 46015 | L2: 46038 | M2: 46031 | N2: 46003 | O2: 46003 | P2: 46008 | Q2: 46003 | R2: 46009 | S2: 46045 | T2: 46059 | U2: 46052 | V2: 46031 | W2: 46052 | X2: 46059 | Y2: 46031
D3: • Functional requirements prioritised (Must / Should / Deferred) | E3: 46015 | F3: 46015 | G3: 46015 | H3: 46015 | I3: 46015 | J3: 46015 | K3: 46015 | L3: 46038 | M3: 46031 | N3: 46003 | O3: 46003 | P3: 46008 | Q3: 46003 | R3: 46009 | S3: 46045 | T3: 46059 | U3: 46052 | V3: 46031 | W3: 46052 | X3: 46059 | Y3: 46031
D4: • In-scope vs out-of-scope clearly defined | E4: 46015 | F4: 46015 | G4: 46015 | H4: 46015 | I4: 46015 | J4: 46015 | K4: 46015 | L4: 46038 | M4: 46031 | N4: 46003 | O4: 46003 | P4: 46008 | Q4: 46003 | R4: 46009 | S4: 46045 | T4: 46059 | U4: 46052 | V4: 46031 | W4: 46052 | X4: 46059 | Y4: 46031
D5: • Dependencies and assumptions explicitly documented | E5: 46015 | F5: 46015 | G5: 46015 | H5: 46015 | I5: 46015 | J5: 46015 | K5: 46015 | L5: 46038 | M5: 46031 | N5: 46003 | O5: 46003 | P5: 46008 | Q5: 46003 | R5: 46009 | S5: 46045 | T5: 46059 | U5: 46052 | V5: 46031 | W5: 46052 | X5: 46059 | Y5: 46031
A6: 2. PRDs Reviewed & Signed Off (NH) | B6: Richard | C6: Confirms shared understanding and agreement with NH to prevent late scope disputes or rework. | D6: • NH review completed
D7: • Explicit NH sign-off received
D8: • No open scope alignment questions
D9: • Any gaps documented, escalated and resolved
A10: 3. UX/UI Designs Completed | B10: Richard (coordination) | C10: Prevents design churn during development and ensures build teams are working from stable designs. | D10: • UX/UI designs completed for all in-scope MVP flows
D11: • Designs reviewed and accepted internally
D12: • Ownership agreed (Vigo vs in-house)
D13: • No critical design work outstanding for sprint execution
A14: 4. Solution Architectures (SAs) Drafted | B14: Richard (coordination) | C14: Grounds delivery commitments in technical reality and surfaces assumptions, risks, and trade-offs early. | D14: • SAs drafted for each epic
D15: • Architecture simplified to MVP
D16: • Technical assumptions and risks explicit
D17: • Key trade-offs documented
A18: 5. SAs Reviewed & Approved | B18: Jerome | C18: Locks technical feasibility before commitments are made and avoids late architectural rework. | D18: • SAs reviewed and approved
D19: • Risks accepted or mitigated
D20: • No unresolved feasibility questions
D21: • Delivery implications understood by Delivery Manager
A22: 6. Sprint Planning by Epic Completed | B22: Richard | C22: Ensures execution commitments are realistic, capacity-aligned, and dependency-aware before development starts. | D22: • Sprint plan complete by epic
D23: • Scope aligned to PRDs, UX/UI, and SAs
D24: • Dependencies explicit
D25: • Capacity and story points validated
A26: 7. Sprint Execution Completed | B26: Richard | C26: Confirms committed sprint scope is fully built and integrated before validation. | D26: • All committed stories meet Definition of Done
D27: • Code merged with reviews completed
D28: • No open critical or high-severity defects
D29: • Sprint review completed and recorded
A30: 8. QA Testing Completed | B30: Caroline | C30: Validates functional correctness and stability prior to business testing. | D30: • Functional and regression tests executed
D31: • Critical/high defects resolved or accepted
D32: • Test summary report completed
D33: • QA sign-off provided
A34: 9. DevOps Deployment to UAT | B34: Jerome | C34: Ensures solution is correctly deployed and stable in the UAT environment. | D34: • Successful deployment to UAT completed
D35: • Environment configuration validated
D36: • Monitoring, logging, and rollback in place
D37: • Release notes shared with UAT stakeholders
A38: 10. UAT Completed & Accepted | B38: Caroline | C38: Confirms solution meets business needs and is approved for production readiness. | D38: • UAT scenarios executed for all in-scope flows
D39: • Business acceptance criteria met
D40: • No unresolved critical/high UAT defects
...

Sheet Weekly 05-Jan
A1: Day | B1: Deliverable / Task | C1: Owner | D1: Stage Gate | E1: RAG | F1: Escalation Request
A2: Monday | B2: Confirm Engineering Team Allocation | C2: Jerome | D2: No | E2: Done
B3: Confirm Capacity and Resource Level Mapping | C3: Jerome | D3: No | E3: Done
B4: Send Plan Dates to Vigo for Designs | C4: Richard | D4: No | E4: Done
B5: External UAT Sanity Checks (R1D) | C5: Caroline | D5: SG8 - QA Complete | E5: Done
A7: Tuesday | B7: Sprint Planning Session 1 for Release 2A | C7: Richard | D7: SG6 - Sprint Planning | E7: In Prog
B8: Internal UAT Complete (R1D) | C8: Caroline | D8: SG8 - QA Complete | E8: Done
A10: Wednesday | B10: UAT Handover to NH (Release 1D) | C10: Caroline | D10: SG8 - QA Complete | F10: Escalation - P2 defect retested in Regression/Internal UAT but not working in Ext UAT
A12: Thursday | B12: Sprint Planning Session 2 for Release 2A | C12: Richard | D12: SG6 - Sprint Planning
A14: Friday | B14: Audit Log Released | C14: Minas | D14: SG1 - PRD | E14: Done
B15: PowerBI Dashboards | C15: Minas | D15: SG1 - PRD
B16: Interim Forecasting Tool | C16: Minas | D16: SG1 - PRD | F16: Escalation - meeting needed with NH - set-up for Weds 8am UK time - Go to green after
B18: Carbon Resource Library | C18: Richard | D18: SG2 - NH Sign-Off
B19: Carbon Item Library | C19: Richard | D19: SG2 - NH Sign-Off
B20: WBS Carbon and Calcs | C20: Richard | D20: SG2 - NH Sign-Off
B21: Baseline Assumption | C21: Richard | D21: SG2 - NH Sign-Off
B22: Calculators and Cost Models | C22: Richard | D22: SG2 - NH Sign-Off
B23: Workflow | C23: Richard | D23: SG2 - NH Sign-Off
B24: EPD | C24: Richard | D24: SG2 - NH Sign-Off
B26: Carbon Resource Library | C26: Richard | D26: SG3 - UX/UI Design | E26: Done
B27: Carbon Item Library | C27: Richard | D27: SG3 - UX/UI Design | E27: Done

Sheet Action Log
A1: ID | B1: Action | C1: Owner | D1: Raised Date | E1: Due Date / RAG | F1: Status
A3: A01 | B3: Confirm SharePoint NH Project Artifacts area is live (master tracker R&R recap folder structure) | C3: Richard | D3: 46027 | E3: 46028 | F3: Done
A5: A02 | B5: Create separate Stage Gate tracking sheet with criteria-level granularity and target dates | C5: Richard | D5: 46027 | E5: 46028 | F5: Done
A7: A03 | B7: Maintain visible daily escalation log carried forward from previous day | C7: Richard | D7: 46027 | E7: 46028 | F7: Done
A9: A04 | B9: Fix 3 x P2 defects blocking internal UAT | C9: Jerome | D9: 46027 | E9: 46028 | F9: Done
A11: A05 | B11: Complete internal UAT execution and issue UAT documentation to Louise | C11: Caroline | D11: 46027 | E11: 46028 | F11: Open
A13: A06 | B13: Finalise onboarding plan for 4 additional engineers chase profiles and shortlist | C13: Jerome | D13: 46027 | E13: 46031 | F13: In Prog
A15: A07 | B15: Confirm Vigo resourcing assumptions remain sufficient | C15: Richard / Jerome | D15: 46027 | E15: 46029 | F15: In Prog
A17: A08 | B17: Brief John Vigo and book design sessions priority LTA then Comparator | C17: Richard | D17: 46027 | E17: 46029 | F17: In Prog
A19: A09 | B19: Re-establish full-team priority alignment session including Vigo | C19: Richard | D19: 46027 | E19: 46031 | F19: Done
A21: A10 | B21: Attend NH IFT clarification meeting | C21: Venkatesh | D21: 46027 | E21: 46029.333 | F21: In Prog
A23: A11 | B23: Post-IFT impact assessment on timeline | C23: Venkatesh / Richard | D23: 46027 | E23: 46030 | F23: Open
A25: A12 | B25: Closely monitor NH PRD sign-offs and flag early slippage | C25: Richard | D25: 46027 | E25: 46029 | F25: Open
